0: 18/02/05 11:50:14 WARN Utils: Your hostname, Tawfiq-PC resolves to a loopback address: 127.0.1.1; using 10.100.228.108 instead (on interface enp0s31f6)
1: 18/02/05 11:50:14 WARN Utils: Set SPARK_LOCAL_IP if you need to bind to another address
2: 18/02/05 11:50:14 WARN NativeCodeLoader: Unable to load native-hadoop library for your platform... using builtin-java classes where applicable
3: Using Spark's default log4j profile: org/apache/spark/log4j-defaults.properties
4: 18/02/05 11:50:15 INFO SparkContext: Running Spark version 2.3.0-SNAPSHOT
5: 18/02/05 11:50:15 INFO SparkContext: Submitted application: BigDataBench WordCount
6: 18/02/05 11:50:15 INFO SecurityManager: Changing view acls to: tawfiq
7: 18/02/05 11:50:15 INFO SecurityManager: Changing modify acls to: tawfiq
8: 18/02/05 11:50:15 INFO SecurityManager: Changing view acls groups to: 
9: 18/02/05 11:50:15 INFO SecurityManager: Changing modify acls groups to: 
10: 18/02/05 11:50:15 INFO SecurityManager: SecurityManager: authentication disabled; ui acls disabled; users  with view permissions: Set(tawfiq); groups with view permissions: Set(); users  with modify permissions: Set(tawfiq); groups with modify permissions: Set()
11: 18/02/05 11:50:15 INFO Utils: Successfully started service 'sparkDriver' on port 40507.
12: 18/02/05 11:50:15 INFO SparkEnv: Registering MapOutputTracker
13: 18/02/05 11:50:15 INFO SparkEnv: Registering BlockManagerMaster
14: 18/02/05 11:50:15 INFO BlockManagerMasterEndpoint: Using org.apache.spark.storage.DefaultTopologyMapper for getting topology information
15: 18/02/05 11:50:15 INFO BlockManagerMasterEndpoint: BlockManagerMasterEndpoint up
16: 18/02/05 11:50:15 INFO DiskBlockManager: Created local directory at /tmp/blockmgr-95280d1c-76d9-4c26-ac9e-6e5188f84fb1
17: 18/02/05 11:50:15 INFO MemoryStore: MemoryStore started with capacity 366.3 MB
18: 18/02/05 11:50:15 INFO SparkEnv: Registering OutputCommitCoordinator
19: 18/02/05 11:50:16 WARN Utils: Service 'SparkUI' could not bind on port 4040. Attempting port 4041.
20: 18/02/05 11:50:16 INFO Utils: Successfully started service 'SparkUI' on port 4041.
21: 18/02/05 11:50:16 INFO SparkUI: Bound SparkUI to 0.0.0.0, and started at http://tawfiq-pc.mobility.unimelb.net.au:4041
22: 18/02/05 11:50:16 INFO SparkContext: Added JAR file:/home/tawfiq/research/spark/bigdatabench-spark_1.3.0-hadoop_1.0.4.jar at spark://tawfiq-pc.mobility.unimelb.net.au:40507/jars/bigdatabench-spark_1.3.0-hadoop_1.0.4.jar with timestamp 1517791816752
23: I0205 11:50:17.937098 14024 sched.cpp:232] Version: 1.4.0
24: I0205 11:50:17.950879 14017 sched.cpp:336] New master detected at master@127.0.0.1:5050
25: I0205 11:50:17.961477 14017 sched.cpp:352] No credentials provided. Attempting to register without authentication
26: I0205 11:50:18.149914 14017 sched.cpp:759] Framework registered with 2da1cbcb-6595-4749-8161-dc163a62b79d-0013
27: 18/02/05 11:50:18 INFO Utils: Successfully started service 'org.apache.spark.network.netty.NettyBlockTransferService' on port 34093.
28: 18/02/05 11:50:18 INFO NettyBlockTransferService: Server created on tawfiq-pc.mobility.unimelb.net.au:34093
29: 18/02/05 11:50:18 INFO BlockManager: Using org.apache.spark.storage.RandomBlockReplicationPolicy for block replication policy
30: 18/02/05 11:50:18 INFO BlockManagerMaster: Registering BlockManager BlockManagerId(driver, tawfiq-pc.mobility.unimelb.net.au, 34093, None)
31: 18/02/05 11:50:18 INFO BlockManagerMasterEndpoint: Registering block manager tawfiq-pc.mobility.unimelb.net.au:34093 with 366.3 MB RAM, BlockManagerId(driver, tawfiq-pc.mobility.unimelb.net.au, 34093, None)
32: 18/02/05 11:50:18 INFO BlockManagerMaster: Registered BlockManager BlockManagerId(driver, tawfiq-pc.mobility.unimelb.net.au, 34093, None)
33: 18/02/05 11:50:18 INFO BlockManager: Initialized BlockManager: BlockManagerId(driver, tawfiq-pc.mobility.unimelb.net.au, 34093, None)
34: 18/02/05 11:50:19 INFO EventLoggingListener: Logging events to file:/home/tawfiq/research/spark/logs/2da1cbcb-6595-4749-8161-dc163a62b79d-0013
35: 18/02/05 11:50:19 INFO MesosCoarseGrainedSchedulerBackend: SchedulerBackend is ready for scheduling beginning after reached minRegisteredResourcesRatio: 0.0
36: 18/02/05 11:50:19 INFO MesosCoarseGrainedSchedulerBackend: Mesos task 0 is now TASK_RUNNING
37: 18/02/05 11:50:19 INFO MemoryStore: Block broadcast_0 stored as values in memory (estimated size 214.5 KB, free 366.1 MB)
38: 18/02/05 11:50:20 INFO MemoryStore: Block broadcast_0_piece0 stored as bytes in memory (estimated size 20.4 KB, free 366.1 MB)
39: 18/02/05 11:50:20 INFO BlockManagerInfo: Added broadcast_0_piece0 in memory on tawfiq-pc.mobility.unimelb.net.au:34093 (size: 20.4 KB, free: 366.3 MB)
40: 18/02/05 11:50:20 INFO SparkContext: Created broadcast 0 from textFile at WordCount.scala:26
41: 18/02/05 11:50:20 INFO FileInputFormat: Total input paths to process : 3
42: 18/02/05 11:50:20 INFO deprecation: mapred.output.dir is deprecated. Instead, use mapreduce.output.fileoutputformat.outputdir
43: 18/02/05 11:50:20 INFO SparkContext: Starting job: runJob at SparkHadoopWriter.scala:78
44: 18/02/05 11:50:20 INFO DAGScheduler: Registering RDD 3 (map at WordCount.scala:28)
45: 18/02/05 11:50:20 INFO DAGScheduler: Got job 0 (runJob at SparkHadoopWriter.scala:78) with 48 output partitions
46: 18/02/05 11:50:20 INFO DAGScheduler: Final stage: ResultStage 1 (runJob at SparkHadoopWriter.scala:78)
47: 18/02/05 11:50:20 INFO DAGScheduler: Parents of final stage: List(ShuffleMapStage 0)
48: 18/02/05 11:50:20 INFO DAGScheduler: Missing parents: List(ShuffleMapStage 0)
49: 18/02/05 11:50:20 INFO DAGScheduler: Submitting ShuffleMapStage 0 (MapPartitionsRDD[3] at map at WordCount.scala:28), which has no missing parents
50: 18/02/05 11:50:20 INFO MemoryStore: Block broadcast_1 stored as values in memory (estimated size 4.8 KB, free 366.1 MB)
51: 18/02/05 11:50:20 INFO MemoryStore: Block broadcast_1_piece0 stored as bytes in memory (estimated size 2.8 KB, free 366.1 MB)
52: 18/02/05 11:50:20 INFO BlockManagerInfo: Added broadcast_1_piece0 in memory on tawfiq-pc.mobility.unimelb.net.au:34093 (size: 2.8 KB, free: 366.3 MB)
53: 18/02/05 11:50:20 INFO SparkContext: Created broadcast 1 from broadcast at DAGScheduler.scala:1029
54: 18/02/05 11:50:20 INFO DAGScheduler: Submitting 48 missing tasks from ShuffleMapStage 0 (MapPartitionsRDD[3] at map at WordCount.scala:28) (first 15 tasks are for partitions Vector(0, 1, 2, 3, 4, 5, 6, 7, 8, 9, 10, 11, 12, 13, 14))
55: 18/02/05 11:50:20 INFO TaskSchedulerImpl: Adding task set 0.0 with 48 tasks
56: 18/02/05 11:50:22 INFO CoarseGrainedSchedulerBackend$DriverEndpoint: Registered executor NettyRpcEndpointRef(spark-client://Executor) (10.100.228.108:33610) with ID 0
57: 18/02/05 11:50:22 INFO TaskSetManager: Starting task 0.0 in stage 0.0 (TID 0, Tawfiq-PC, executor 0, partition 0, PROCESS_LOCAL, 7911 bytes)
58: 18/02/05 11:50:22 INFO BlockManagerMasterEndpoint: Registering block manager Tawfiq-PC:38949 with 912.3 MB RAM, BlockManagerId(0, Tawfiq-PC, 38949, None)
59: 18/02/05 11:50:22 INFO BlockManagerInfo: Added broadcast_1_piece0 in memory on Tawfiq-PC:38949 (size: 2.8 KB, free: 912.3 MB)
60: 18/02/05 11:50:22 INFO BlockManagerInfo: Added broadcast_0_piece0 in memory on Tawfiq-PC:38949 (size: 20.4 KB, free: 912.3 MB)
61: 18/02/05 11:50:24 INFO TaskSetManager: Starting task 1.0 in stage 0.0 (TID 1, Tawfiq-PC, executor 0, partition 1, PROCESS_LOCAL, 7911 bytes)
62: 18/02/05 11:50:24 INFO TaskSetManager: Finished task 0.0 in stage 0.0 (TID 0) in 2803 ms on Tawfiq-PC (executor 0) (1/48)
63: 18/02/05 11:50:25 INFO TaskSetManager: Starting task 2.0 in stage 0.0 (TID 2, Tawfiq-PC, executor 0, partition 2, PROCESS_LOCAL, 7911 bytes)
64: 18/02/05 11:50:25 INFO TaskSetManager: Finished task 1.0 in stage 0.0 (TID 1) in 1062 ms on Tawfiq-PC (executor 0) (2/48)
65: 18/02/05 11:50:26 INFO TaskSetManager: Starting task 3.0 in stage 0.0 (TID 3, Tawfiq-PC, executor 0, partition 3, PROCESS_LOCAL, 7911 bytes)
66: 18/02/05 11:50:26 INFO TaskSetManager: Finished task 2.0 in stage 0.0 (TID 2) in 1086 ms on Tawfiq-PC (executor 0) (3/48)
67: 18/02/05 11:50:28 INFO TaskSetManager: Starting task 4.0 in stage 0.0 (TID 4, Tawfiq-PC, executor 0, partition 4, PROCESS_LOCAL, 7911 bytes)
68: 18/02/05 11:50:28 INFO TaskSetManager: Finished task 3.0 in stage 0.0 (TID 3) in 1250 ms on Tawfiq-PC (executor 0) (4/48)
69: 18/02/05 11:50:29 INFO TaskSetManager: Starting task 5.0 in stage 0.0 (TID 5, Tawfiq-PC, executor 0, partition 5, PROCESS_LOCAL, 7911 bytes)
70: 18/02/05 11:50:29 INFO TaskSetManager: Finished task 4.0 in stage 0.0 (TID 4) in 1003 ms on Tawfiq-PC (executor 0) (5/48)
71: 18/02/05 11:50:30 INFO TaskSetManager: Starting task 6.0 in stage 0.0 (TID 6, Tawfiq-PC, executor 0, partition 6, PROCESS_LOCAL, 7911 bytes)
72: 18/02/05 11:50:30 INFO TaskSetManager: Finished task 5.0 in stage 0.0 (TID 5) in 920 ms on Tawfiq-PC (executor 0) (6/48)
73: 18/02/05 11:50:31 INFO TaskSetManager: Starting task 7.0 in stage 0.0 (TID 7, Tawfiq-PC, executor 0, partition 7, PROCESS_LOCAL, 7911 bytes)
74: 18/02/05 11:50:31 INFO TaskSetManager: Finished task 6.0 in stage 0.0 (TID 6) in 1001 ms on Tawfiq-PC (executor 0) (7/48)
75: 18/02/05 11:50:32 INFO TaskSetManager: Starting task 8.0 in stage 0.0 (TID 8, Tawfiq-PC, executor 0, partition 8, PROCESS_LOCAL, 7911 bytes)
76: 18/02/05 11:50:32 INFO TaskSetManager: Finished task 7.0 in stage 0.0 (TID 7) in 1006 ms on Tawfiq-PC (executor 0) (8/48)
77: 18/02/05 11:50:33 INFO TaskSetManager: Starting task 9.0 in stage 0.0 (TID 9, Tawfiq-PC, executor 0, partition 9, PROCESS_LOCAL, 7911 bytes)
78: 18/02/05 11:50:33 INFO TaskSetManager: Finished task 8.0 in stage 0.0 (TID 8) in 1007 ms on Tawfiq-PC (executor 0) (9/48)
79: 18/02/05 11:50:33 INFO TaskSetManager: Starting task 10.0 in stage 0.0 (TID 10, Tawfiq-PC, executor 0, partition 10, PROCESS_LOCAL, 7911 bytes)
80: 18/02/05 11:50:33 INFO TaskSetManager: Finished task 9.0 in stage 0.0 (TID 9) in 891 ms on Tawfiq-PC (executor 0) (10/48)
81: 18/02/05 11:50:34 INFO TaskSetManager: Starting task 11.0 in stage 0.0 (TID 11, Tawfiq-PC, executor 0, partition 11, PROCESS_LOCAL, 7911 bytes)
82: 18/02/05 11:50:34 INFO TaskSetManager: Finished task 10.0 in stage 0.0 (TID 10) in 997 ms on Tawfiq-PC (executor 0) (11/48)
83: 18/02/05 11:50:35 INFO TaskSetManager: Starting task 12.0 in stage 0.0 (TID 12, Tawfiq-PC, executor 0, partition 12, PROCESS_LOCAL, 7911 bytes)
84: 18/02/05 11:50:35 INFO TaskSetManager: Finished task 11.0 in stage 0.0 (TID 11) in 906 ms on Tawfiq-PC (executor 0) (12/48)
85: 18/02/05 11:50:36 INFO TaskSetManager: Starting task 13.0 in stage 0.0 (TID 13, Tawfiq-PC, executor 0, partition 13, PROCESS_LOCAL, 7911 bytes)
86: 18/02/05 11:50:36 INFO TaskSetManager: Finished task 12.0 in stage 0.0 (TID 12) in 940 ms on Tawfiq-PC (executor 0) (13/48)
87: 18/02/05 11:50:37 INFO TaskSetManager: Starting task 14.0 in stage 0.0 (TID 14, Tawfiq-PC, executor 0, partition 14, PROCESS_LOCAL, 7911 bytes)
88: 18/02/05 11:50:37 INFO TaskSetManager: Finished task 13.0 in stage 0.0 (TID 13) in 1137 ms on Tawfiq-PC (executor 0) (14/48)
89: 18/02/05 11:50:39 INFO TaskSetManager: Starting task 15.0 in stage 0.0 (TID 15, Tawfiq-PC, executor 0, partition 15, PROCESS_LOCAL, 7911 bytes)
90: 18/02/05 11:50:39 INFO TaskSetManager: Finished task 14.0 in stage 0.0 (TID 14) in 1650 ms on Tawfiq-PC (executor 0) (15/48)
91: 18/02/05 11:50:40 INFO TaskSetManager: Starting task 16.0 in stage 0.0 (TID 16, Tawfiq-PC, executor 0, partition 16, PROCESS_LOCAL, 7907 bytes)
92: 18/02/05 11:50:40 INFO TaskSetManager: Finished task 15.0 in stage 0.0 (TID 15) in 984 ms on Tawfiq-PC (executor 0) (16/48)
93: 18/02/05 11:50:41 INFO TaskSetManager: Starting task 17.0 in stage 0.0 (TID 17, Tawfiq-PC, executor 0, partition 17, PROCESS_LOCAL, 7907 bytes)
94: 18/02/05 11:50:41 INFO TaskSetManager: Finished task 16.0 in stage 0.0 (TID 16) in 1435 ms on Tawfiq-PC (executor 0) (17/48)
95: 18/02/05 11:50:43 INFO TaskSetManager: Starting task 18.0 in stage 0.0 (TID 18, Tawfiq-PC, executor 0, partition 18, PROCESS_LOCAL, 7907 bytes)
96: 18/02/05 11:50:43 INFO TaskSetManager: Finished task 17.0 in stage 0.0 (TID 17) in 1596 ms on Tawfiq-PC (executor 0) (18/48)
97: 18/02/05 11:50:45 INFO TaskSetManager: Starting task 19.0 in stage 0.0 (TID 19, Tawfiq-PC, executor 0, partition 19, PROCESS_LOCAL, 7907 bytes)
98: 18/02/05 11:50:45 INFO TaskSetManager: Finished task 18.0 in stage 0.0 (TID 18) in 1979 ms on Tawfiq-PC (executor 0) (19/48)
99: 18/02/05 11:50:47 INFO TaskSetManager: Starting task 20.0 in stage 0.0 (TID 20, Tawfiq-PC, executor 0, partition 20, PROCESS_LOCAL, 7907 bytes)
100: 18/02/05 11:50:47 INFO TaskSetManager: Finished task 19.0 in stage 0.0 (TID 19) in 2066 ms on Tawfiq-PC (executor 0) (20/48)
101: 18/02/05 11:50:49 INFO TaskSetManager: Starting task 21.0 in stage 0.0 (TID 21, Tawfiq-PC, executor 0, partition 21, PROCESS_LOCAL, 7907 bytes)
102: 18/02/05 11:50:49 INFO TaskSetManager: Finished task 20.0 in stage 0.0 (TID 20) in 2269 ms on Tawfiq-PC (executor 0) (21/48)
103: 18/02/05 11:50:51 INFO TaskSetManager: Starting task 22.0 in stage 0.0 (TID 22, Tawfiq-PC, executor 0, partition 22, PROCESS_LOCAL, 7907 bytes)
104: 18/02/05 11:50:51 INFO TaskSetManager: Finished task 21.0 in stage 0.0 (TID 21) in 1750 ms on Tawfiq-PC (executor 0) (22/48)
105: 18/02/05 11:50:52 INFO TaskSetManager: Starting task 23.0 in stage 0.0 (TID 23, Tawfiq-PC, executor 0, partition 23, PROCESS_LOCAL, 7907 bytes)
106: 18/02/05 11:50:52 INFO TaskSetManager: Finished task 22.0 in stage 0.0 (TID 22) in 963 ms on Tawfiq-PC (executor 0) (23/48)
107: 18/02/05 11:50:53 INFO TaskSetManager: Starting task 24.0 in stage 0.0 (TID 24, Tawfiq-PC, executor 0, partition 24, PROCESS_LOCAL, 7907 bytes)
108: 18/02/05 11:50:53 INFO TaskSetManager: Finished task 23.0 in stage 0.0 (TID 23) in 1382 ms on Tawfiq-PC (executor 0) (24/48)
109: 18/02/05 11:50:54 INFO TaskSetManager: Starting task 25.0 in stage 0.0 (TID 25, Tawfiq-PC, executor 0, partition 25, PROCESS_LOCAL, 7907 bytes)
110: 18/02/05 11:50:54 INFO TaskSetManager: Finished task 24.0 in stage 0.0 (TID 24) in 879 ms on Tawfiq-PC (executor 0) (25/48)
111: 18/02/05 11:50:56 INFO TaskSetManager: Starting task 26.0 in stage 0.0 (TID 26, Tawfiq-PC, executor 0, partition 26, PROCESS_LOCAL, 7907 bytes)
112: 18/02/05 11:50:56 INFO TaskSetManager: Finished task 25.0 in stage 0.0 (TID 25) in 1267 ms on Tawfiq-PC (executor 0) (26/48)
113: 18/02/05 11:50:57 INFO TaskSetManager: Starting task 27.0 in stage 0.0 (TID 27, Tawfiq-PC, executor 0, partition 27, PROCESS_LOCAL, 7907 bytes)
114: 18/02/05 11:50:57 INFO TaskSetManager: Finished task 26.0 in stage 0.0 (TID 26) in 1013 ms on Tawfiq-PC (executor 0) (27/48)
115: 18/02/05 11:50:58 INFO TaskSetManager: Starting task 28.0 in stage 0.0 (TID 28, Tawfiq-PC, executor 0, partition 28, PROCESS_LOCAL, 7907 bytes)
116: 18/02/05 11:50:58 INFO TaskSetManager: Finished task 27.0 in stage 0.0 (TID 27) in 1522 ms on Tawfiq-PC (executor 0) (28/48)
117: 18/02/05 11:50:59 INFO TaskSetManager: Starting task 29.0 in stage 0.0 (TID 29, Tawfiq-PC, executor 0, partition 29, PROCESS_LOCAL, 7907 bytes)
118: 18/02/05 11:50:59 INFO TaskSetManager: Finished task 28.0 in stage 0.0 (TID 28) in 1258 ms on Tawfiq-PC (executor 0) (29/48)
119: 18/02/05 11:51:00 INFO TaskSetManager: Starting task 30.0 in stage 0.0 (TID 30, Tawfiq-PC, executor 0, partition 30, PROCESS_LOCAL, 7907 bytes)
120: 18/02/05 11:51:00 INFO TaskSetManager: Finished task 29.0 in stage 0.0 (TID 29) in 1057 ms on Tawfiq-PC (executor 0) (30/48)
121: 18/02/05 11:51:02 INFO TaskSetManager: Starting task 31.0 in stage 0.0 (TID 31, Tawfiq-PC, executor 0, partition 31, PROCESS_LOCAL, 7907 bytes)
122: 18/02/05 11:51:02 INFO TaskSetManager: Finished task 30.0 in stage 0.0 (TID 30) in 1203 ms on Tawfiq-PC (executor 0) (31/48)
123: 18/02/05 11:51:02 INFO TaskSetManager: Starting task 32.0 in stage 0.0 (TID 32, Tawfiq-PC, executor 0, partition 32, PROCESS_LOCAL, 7900 bytes)
124: 18/02/05 11:51:02 INFO TaskSetManager: Finished task 31.0 in stage 0.0 (TID 31) in 802 ms on Tawfiq-PC (executor 0) (32/48)
125: 18/02/05 11:51:04 INFO TaskSetManager: Starting task 33.0 in stage 0.0 (TID 33, Tawfiq-PC, executor 0, partition 33, PROCESS_LOCAL, 7900 bytes)
126: 18/02/05 11:51:04 INFO TaskSetManager: Finished task 32.0 in stage 0.0 (TID 32) in 1080 ms on Tawfiq-PC (executor 0) (33/48)
127: 18/02/05 11:51:05 INFO TaskSetManager: Starting task 34.0 in stage 0.0 (TID 34, Tawfiq-PC, executor 0, partition 34, PROCESS_LOCAL, 7900 bytes)
128: 18/02/05 11:51:05 INFO TaskSetManager: Finished task 33.0 in stage 0.0 (TID 33) in 1023 ms on Tawfiq-PC (executor 0) (34/48)
129: 18/02/05 11:51:06 INFO TaskSetManager: Starting task 35.0 in stage 0.0 (TID 35, Tawfiq-PC, executor 0, partition 35, PROCESS_LOCAL, 7900 bytes)
130: 18/02/05 11:51:06 INFO TaskSetManager: Finished task 34.0 in stage 0.0 (TID 34) in 998 ms on Tawfiq-PC (executor 0) (35/48)
131: 18/02/05 11:51:07 INFO TaskSetManager: Starting task 36.0 in stage 0.0 (TID 36, Tawfiq-PC, executor 0, partition 36, PROCESS_LOCAL, 7900 bytes)
132: 18/02/05 11:51:07 INFO TaskSetManager: Finished task 35.0 in stage 0.0 (TID 35) in 1194 ms on Tawfiq-PC (executor 0) (36/48)
133: 18/02/05 11:51:08 INFO TaskSetManager: Starting task 37.0 in stage 0.0 (TID 37, Tawfiq-PC, executor 0, partition 37, PROCESS_LOCAL, 7900 bytes)
134: 18/02/05 11:51:08 INFO TaskSetManager: Finished task 36.0 in stage 0.0 (TID 36) in 1252 ms on Tawfiq-PC (executor 0) (37/48)
135: 18/02/05 11:51:09 INFO TaskSetManager: Starting task 38.0 in stage 0.0 (TID 38, Tawfiq-PC, executor 0, partition 38, PROCESS_LOCAL, 7900 bytes)
136: 18/02/05 11:51:09 INFO TaskSetManager: Finished task 37.0 in stage 0.0 (TID 37) in 1044 ms on Tawfiq-PC (executor 0) (38/48)
137: 18/02/05 11:51:11 INFO TaskSetManager: Starting task 39.0 in stage 0.0 (TID 39, Tawfiq-PC, executor 0, partition 39, PROCESS_LOCAL, 7900 bytes)
138: 18/02/05 11:51:11 INFO TaskSetManager: Finished task 38.0 in stage 0.0 (TID 38) in 1493 ms on Tawfiq-PC (executor 0) (39/48)
139: 18/02/05 11:51:12 INFO TaskSetManager: Starting task 40.0 in stage 0.0 (TID 40, Tawfiq-PC, executor 0, partition 40, PROCESS_LOCAL, 7900 bytes)
140: 18/02/05 11:51:12 INFO TaskSetManager: Finished task 39.0 in stage 0.0 (TID 39) in 1356 ms on Tawfiq-PC (executor 0) (40/48)
141: 18/02/05 11:51:14 INFO TaskSetManager: Starting task 41.0 in stage 0.0 (TID 41, Tawfiq-PC, executor 0, partition 41, PROCESS_LOCAL, 7900 bytes)
142: 18/02/05 11:51:14 INFO TaskSetManager: Finished task 40.0 in stage 0.0 (TID 40) in 1862 ms on Tawfiq-PC (executor 0) (41/48)
143: 18/02/05 11:51:15 INFO TaskSetManager: Starting task 42.0 in stage 0.0 (TID 42, Tawfiq-PC, executor 0, partition 42, PROCESS_LOCAL, 7900 bytes)
144: 18/02/05 11:51:15 INFO TaskSetManager: Finished task 41.0 in stage 0.0 (TID 41) in 1430 ms on Tawfiq-PC (executor 0) (42/48)
145: 18/02/05 11:51:16 INFO TaskSetManager: Starting task 43.0 in stage 0.0 (TID 43, Tawfiq-PC, executor 0, partition 43, PROCESS_LOCAL, 7900 bytes)
146: 18/02/05 11:51:16 INFO TaskSetManager: Finished task 42.0 in stage 0.0 (TID 42) in 1064 ms on Tawfiq-PC (executor 0) (43/48)
147: 18/02/05 11:51:17 INFO TaskSetManager: Starting task 44.0 in stage 0.0 (TID 44, Tawfiq-PC, executor 0, partition 44, PROCESS_LOCAL, 7900 bytes)
148: 18/02/05 11:51:17 INFO TaskSetManager: Finished task 43.0 in stage 0.0 (TID 43) in 758 ms on Tawfiq-PC (executor 0) (44/48)
149: 18/02/05 11:51:18 INFO TaskSetManager: Starting task 45.0 in stage 0.0 (TID 45, Tawfiq-PC, executor 0, partition 45, PROCESS_LOCAL, 7900 bytes)
150: 18/02/05 11:51:18 INFO TaskSetManager: Finished task 44.0 in stage 0.0 (TID 44) in 1075 ms on Tawfiq-PC (executor 0) (45/48)
151: 18/02/05 11:51:19 INFO TaskSetManager: Starting task 46.0 in stage 0.0 (TID 46, Tawfiq-PC, executor 0, partition 46, PROCESS_LOCAL, 7900 bytes)
152: 18/02/05 11:51:19 INFO TaskSetManager: Finished task 45.0 in stage 0.0 (TID 45) in 911 ms on Tawfiq-PC (executor 0) (46/48)
153: 18/02/05 11:51:20 INFO TaskSetManager: Starting task 47.0 in stage 0.0 (TID 47, Tawfiq-PC, executor 0, partition 47, PROCESS_LOCAL, 7900 bytes)
154: 18/02/05 11:51:20 INFO TaskSetManager: Finished task 46.0 in stage 0.0 (TID 46) in 867 ms on Tawfiq-PC (executor 0) (47/48)
155: 18/02/05 11:51:20 INFO TaskSetManager: Finished task 47.0 in stage 0.0 (TID 47) in 585 ms on Tawfiq-PC (executor 0) (48/48)
156: 18/02/05 11:51:20 INFO TaskSchedulerImpl: Removed TaskSet 0.0, whose tasks have all completed, from pool 
157: 18/02/05 11:51:20 INFO DAGScheduler: ShuffleMapStage 0 (map at WordCount.scala:28) finished in 60.237 s
158: 18/02/05 11:51:20 INFO DAGScheduler: looking for newly runnable stages
159: 18/02/05 11:51:20 INFO DAGScheduler: running: Set()
160: 18/02/05 11:51:20 INFO DAGScheduler: waiting: Set(ResultStage 1)
161: 18/02/05 11:51:20 INFO DAGScheduler: failed: Set()
162: 18/02/05 11:51:20 INFO DAGScheduler: Submitting ResultStage 1 (MapPartitionsRDD[5] at saveAsTextFile at WordCount.scala:31), which has no missing parents
163: 18/02/05 11:51:20 INFO MemoryStore: Block broadcast_2 stored as values in memory (estimated size 65.6 KB, free 366.0 MB)
164: 18/02/05 11:51:20 INFO MemoryStore: Block broadcast_2_piece0 stored as bytes in memory (estimated size 23.6 KB, free 366.0 MB)
165: 18/02/05 11:51:20 INFO BlockManagerInfo: Added broadcast_2_piece0 in memory on tawfiq-pc.mobility.unimelb.net.au:34093 (size: 23.6 KB, free: 366.3 MB)
166: 18/02/05 11:51:20 INFO SparkContext: Created broadcast 2 from broadcast at DAGScheduler.scala:1029
167: 18/02/05 11:51:20 INFO DAGScheduler: Submitting 48 missing tasks from ResultStage 1 (MapPartitionsRDD[5] at saveAsTextFile at WordCount.scala:31) (first 15 tasks are for partitions Vector(0, 1, 2, 3, 4, 5, 6, 7, 8, 9, 10, 11, 12, 13, 14))
168: 18/02/05 11:51:20 INFO TaskSchedulerImpl: Adding task set 1.0 with 48 tasks
169: 18/02/05 11:51:20 INFO TaskSetManager: Starting task 0.0 in stage 1.0 (TID 48, Tawfiq-PC, executor 0, partition 0, NODE_LOCAL, 7671 bytes)
170: 18/02/05 11:51:20 INFO BlockManagerInfo: Added broadcast_2_piece0 in memory on Tawfiq-PC:38949 (size: 23.6 KB, free: 912.3 MB)
171: 18/02/05 11:51:21 INFO MapOutputTrackerMasterEndpoint: Asked to send map output locations for shuffle 0 to 10.100.228.108:33610
172: 18/02/05 11:51:21 INFO TaskSetManager: Starting task 1.0 in stage 1.0 (TID 49, Tawfiq-PC, executor 0, partition 1, NODE_LOCAL, 7671 bytes)
173: 18/02/05 11:51:21 INFO TaskSetManager: Finished task 0.0 in stage 1.0 (TID 48) in 311 ms on Tawfiq-PC (executor 0) (1/48)
174: 18/02/05 11:51:21 INFO TaskSetManager: Starting task 2.0 in stage 1.0 (TID 50, Tawfiq-PC, executor 0, partition 2, NODE_LOCAL, 7671 bytes)
175: 18/02/05 11:51:21 INFO TaskSetManager: Finished task 1.0 in stage 1.0 (TID 49) in 157 ms on Tawfiq-PC (executor 0) (2/48)
176: 18/02/05 11:51:21 INFO TaskSetManager: Starting task 3.0 in stage 1.0 (TID 51, Tawfiq-PC, executor 0, partition 3, NODE_LOCAL, 7671 bytes)
177: 18/02/05 11:51:21 INFO TaskSetManager: Finished task 2.0 in stage 1.0 (TID 50) in 98 ms on Tawfiq-PC (executor 0) (3/48)
178: 18/02/05 11:51:21 INFO TaskSetManager: Starting task 4.0 in stage 1.0 (TID 52, Tawfiq-PC, executor 0, partition 4, NODE_LOCAL, 7671 bytes)
179: 18/02/05 11:51:21 INFO TaskSetManager: Finished task 3.0 in stage 1.0 (TID 51) in 77 ms on Tawfiq-PC (executor 0) (4/48)
180: 18/02/05 11:51:21 INFO TaskSetManager: Starting task 5.0 in stage 1.0 (TID 53, Tawfiq-PC, executor 0, partition 5, NODE_LOCAL, 7671 bytes)
181: 18/02/05 11:51:21 INFO TaskSetManager: Finished task 4.0 in stage 1.0 (TID 52) in 76 ms on Tawfiq-PC (executor 0) (5/48)
182: 18/02/05 11:51:21 INFO TaskSetManager: Starting task 6.0 in stage 1.0 (TID 54, Tawfiq-PC, executor 0, partition 6, NODE_LOCAL, 7671 bytes)
183: 18/02/05 11:51:21 INFO TaskSetManager: Finished task 5.0 in stage 1.0 (TID 53) in 86 ms on Tawfiq-PC (executor 0) (6/48)
184: 18/02/05 11:51:21 INFO TaskSetManager: Starting task 7.0 in stage 1.0 (TID 55, Tawfiq-PC, executor 0, partition 7, NODE_LOCAL, 7671 bytes)
185: 18/02/05 11:51:21 INFO TaskSetManager: Finished task 6.0 in stage 1.0 (TID 54) in 97 ms on Tawfiq-PC (executor 0) (7/48)
186: 18/02/05 11:51:21 INFO TaskSetManager: Starting task 8.0 in stage 1.0 (TID 56, Tawfiq-PC, executor 0, partition 8, NODE_LOCAL, 7671 bytes)
187: 18/02/05 11:51:21 INFO TaskSetManager: Finished task 7.0 in stage 1.0 (TID 55) in 91 ms on Tawfiq-PC (executor 0) (8/48)
188: 18/02/05 11:51:22 INFO TaskSetManager: Starting task 9.0 in stage 1.0 (TID 57, Tawfiq-PC, executor 0, partition 9, NODE_LOCAL, 7671 bytes)
189: 18/02/05 11:51:22 INFO TaskSetManager: Finished task 8.0 in stage 1.0 (TID 56) in 55 ms on Tawfiq-PC (executor 0) (9/48)
190: 18/02/05 11:51:22 INFO TaskSetManager: Starting task 10.0 in stage 1.0 (TID 58, Tawfiq-PC, executor 0, partition 10, NODE_LOCAL, 7671 bytes)
191: 18/02/05 11:51:22 INFO TaskSetManager: Finished task 9.0 in stage 1.0 (TID 57) in 43 ms on Tawfiq-PC (executor 0) (10/48)
192: 18/02/05 11:51:22 INFO TaskSetManager: Starting task 11.0 in stage 1.0 (TID 59, Tawfiq-PC, executor 0, partition 11, NODE_LOCAL, 7671 bytes)
193: 18/02/05 11:51:22 INFO TaskSetManager: Finished task 10.0 in stage 1.0 (TID 58) in 54 ms on Tawfiq-PC (executor 0) (11/48)
194: 18/02/05 11:51:22 INFO TaskSetManager: Starting task 12.0 in stage 1.0 (TID 60, Tawfiq-PC, executor 0, partition 12, NODE_LOCAL, 7671 bytes)
195: 18/02/05 11:51:22 INFO TaskSetManager: Finished task 11.0 in stage 1.0 (TID 59) in 51 ms on Tawfiq-PC (executor 0) (12/48)
196: 18/02/05 11:51:22 INFO TaskSetManager: Starting task 13.0 in stage 1.0 (TID 61, Tawfiq-PC, executor 0, partition 13, NODE_LOCAL, 7671 bytes)
197: 18/02/05 11:51:22 INFO TaskSetManager: Finished task 12.0 in stage 1.0 (TID 60) in 55 ms on Tawfiq-PC (executor 0) (13/48)
198: 18/02/05 11:51:22 INFO TaskSetManager: Starting task 14.0 in stage 1.0 (TID 62, Tawfiq-PC, executor 0, partition 14, NODE_LOCAL, 7671 bytes)
199: 18/02/05 11:51:22 INFO TaskSetManager: Finished task 13.0 in stage 1.0 (TID 61) in 60 ms on Tawfiq-PC (executor 0) (14/48)
200: 18/02/05 11:51:22 INFO TaskSetManager: Starting task 15.0 in stage 1.0 (TID 63, Tawfiq-PC, executor 0, partition 15, NODE_LOCAL, 7671 bytes)
201: 18/02/05 11:51:22 INFO TaskSetManager: Finished task 14.0 in stage 1.0 (TID 62) in 56 ms on Tawfiq-PC (executor 0) (15/48)
202: 18/02/05 11:51:22 INFO TaskSetManager: Starting task 16.0 in stage 1.0 (TID 64, Tawfiq-PC, executor 0, partition 16, NODE_LOCAL, 7671 bytes)
203: 18/02/05 11:51:22 INFO TaskSetManager: Finished task 15.0 in stage 1.0 (TID 63) in 67 ms on Tawfiq-PC (executor 0) (16/48)
204: 18/02/05 11:51:22 INFO TaskSetManager: Starting task 17.0 in stage 1.0 (TID 65, Tawfiq-PC, executor 0, partition 17, NODE_LOCAL, 7671 bytes)
205: 18/02/05 11:51:22 INFO TaskSetManager: Finished task 16.0 in stage 1.0 (TID 64) in 50 ms on Tawfiq-PC (executor 0) (17/48)
206: 18/02/05 11:51:22 INFO TaskSetManager: Starting task 18.0 in stage 1.0 (TID 66, Tawfiq-PC, executor 0, partition 18, NODE_LOCAL, 7671 bytes)
207: 18/02/05 11:51:22 INFO TaskSetManager: Finished task 17.0 in stage 1.0 (TID 65) in 45 ms on Tawfiq-PC (executor 0) (18/48)
208: 18/02/05 11:51:22 INFO TaskSetManager: Starting task 19.0 in stage 1.0 (TID 67, Tawfiq-PC, executor 0, partition 19, NODE_LOCAL, 7671 bytes)
209: 18/02/05 11:51:22 INFO TaskSetManager: Finished task 18.0 in stage 1.0 (TID 66) in 31 ms on Tawfiq-PC (executor 0) (19/48)
210: 18/02/05 11:51:22 INFO TaskSetManager: Starting task 20.0 in stage 1.0 (TID 68, Tawfiq-PC, executor 0, partition 20, NODE_LOCAL, 7671 bytes)
211: 18/02/05 11:51:22 INFO TaskSetManager: Finished task 19.0 in stage 1.0 (TID 67) in 43 ms on Tawfiq-PC (executor 0) (20/48)
212: 18/02/05 11:51:22 INFO TaskSetManager: Starting task 21.0 in stage 1.0 (TID 69, Tawfiq-PC, executor 0, partition 21, NODE_LOCAL, 7671 bytes)
213: 18/02/05 11:51:22 INFO TaskSetManager: Finished task 20.0 in stage 1.0 (TID 68) in 48 ms on Tawfiq-PC (executor 0) (21/48)
214: 18/02/05 11:51:22 INFO TaskSetManager: Starting task 22.0 in stage 1.0 (TID 70, Tawfiq-PC, executor 0, partition 22, NODE_LOCAL, 7671 bytes)
215: 18/02/05 11:51:22 INFO TaskSetManager: Finished task 21.0 in stage 1.0 (TID 69) in 37 ms on Tawfiq-PC (executor 0) (22/48)
216: 18/02/05 11:51:22 INFO TaskSetManager: Starting task 23.0 in stage 1.0 (TID 71, Tawfiq-PC, executor 0, partition 23, NODE_LOCAL, 7671 bytes)
217: 18/02/05 11:51:22 INFO TaskSetManager: Finished task 22.0 in stage 1.0 (TID 70) in 31 ms on Tawfiq-PC (executor 0) (23/48)
218: 18/02/05 11:51:22 INFO TaskSetManager: Starting task 24.0 in stage 1.0 (TID 72, Tawfiq-PC, executor 0, partition 24, NODE_LOCAL, 7671 bytes)
219: 18/02/05 11:51:22 INFO TaskSetManager: Finished task 23.0 in stage 1.0 (TID 71) in 23 ms on Tawfiq-PC (executor 0) (24/48)
220: 18/02/05 11:51:22 INFO TaskSetManager: Starting task 25.0 in stage 1.0 (TID 73, Tawfiq-PC, executor 0, partition 25, NODE_LOCAL, 7671 bytes)
221: 18/02/05 11:51:22 INFO TaskSetManager: Finished task 24.0 in stage 1.0 (TID 72) in 27 ms on Tawfiq-PC (executor 0) (25/48)
222: 18/02/05 11:51:22 INFO TaskSetManager: Starting task 26.0 in stage 1.0 (TID 74, Tawfiq-PC, executor 0, partition 26, NODE_LOCAL, 7671 bytes)
223: 18/02/05 11:51:22 INFO TaskSetManager: Finished task 25.0 in stage 1.0 (TID 73) in 21 ms on Tawfiq-PC (executor 0) (26/48)
224: 18/02/05 11:51:22 INFO TaskSetManager: Starting task 27.0 in stage 1.0 (TID 75, Tawfiq-PC, executor 0, partition 27, NODE_LOCAL, 7671 bytes)
225: 18/02/05 11:51:22 INFO TaskSetManager: Finished task 26.0 in stage 1.0 (TID 74) in 31 ms on Tawfiq-PC (executor 0) (27/48)
226: 18/02/05 11:51:22 INFO TaskSetManager: Starting task 28.0 in stage 1.0 (TID 76, Tawfiq-PC, executor 0, partition 28, NODE_LOCAL, 7671 bytes)
227: 18/02/05 11:51:22 INFO TaskSetManager: Finished task 27.0 in stage 1.0 (TID 75) in 35 ms on Tawfiq-PC (executor 0) (28/48)
228: 18/02/05 11:51:22 INFO TaskSetManager: Starting task 29.0 in stage 1.0 (TID 77, Tawfiq-PC, executor 0, partition 29, NODE_LOCAL, 7671 bytes)
229: 18/02/05 11:51:22 INFO TaskSetManager: Finished task 28.0 in stage 1.0 (TID 76) in 38 ms on Tawfiq-PC (executor 0) (29/48)
230: 18/02/05 11:51:22 INFO TaskSetManager: Starting task 30.0 in stage 1.0 (TID 78, Tawfiq-PC, executor 0, partition 30, NODE_LOCAL, 7671 bytes)
231: 18/02/05 11:51:22 INFO TaskSetManager: Finished task 29.0 in stage 1.0 (TID 77) in 41 ms on Tawfiq-PC (executor 0) (30/48)
232: 18/02/05 11:51:22 INFO TaskSetManager: Starting task 31.0 in stage 1.0 (TID 79, Tawfiq-PC, executor 0, partition 31, NODE_LOCAL, 7671 bytes)
233: 18/02/05 11:51:22 INFO TaskSetManager: Finished task 30.0 in stage 1.0 (TID 78) in 53 ms on Tawfiq-PC (executor 0) (31/48)
234: 18/02/05 11:51:22 INFO TaskSetManager: Starting task 32.0 in stage 1.0 (TID 80, Tawfiq-PC, executor 0, partition 32, NODE_LOCAL, 7671 bytes)
235: 18/02/05 11:51:22 INFO TaskSetManager: Finished task 31.0 in stage 1.0 (TID 79) in 49 ms on Tawfiq-PC (executor 0) (32/48)
236: 18/02/05 11:51:23 INFO TaskSetManager: Starting task 33.0 in stage 1.0 (TID 81, Tawfiq-PC, executor 0, partition 33, NODE_LOCAL, 7671 bytes)
237: 18/02/05 11:51:23 INFO TaskSetManager: Finished task 32.0 in stage 1.0 (TID 80) in 31 ms on Tawfiq-PC (executor 0) (33/48)
238: 18/02/05 11:51:23 INFO TaskSetManager: Starting task 34.0 in stage 1.0 (TID 82, Tawfiq-PC, executor 0, partition 34, NODE_LOCAL, 7671 bytes)
239: 18/02/05 11:51:23 INFO TaskSetManager: Finished task 33.0 in stage 1.0 (TID 81) in 32 ms on Tawfiq-PC (executor 0) (34/48)
240: 18/02/05 11:51:23 INFO TaskSetManager: Starting task 35.0 in stage 1.0 (TID 83, Tawfiq-PC, executor 0, partition 35, NODE_LOCAL, 7671 bytes)
241: 18/02/05 11:51:23 INFO TaskSetManager: Finished task 34.0 in stage 1.0 (TID 82) in 35 ms on Tawfiq-PC (executor 0) (35/48)
242: 18/02/05 11:51:23 INFO TaskSetManager: Starting task 36.0 in stage 1.0 (TID 84, Tawfiq-PC, executor 0, partition 36, NODE_LOCAL, 7671 bytes)
243: 18/02/05 11:51:23 INFO TaskSetManager: Finished task 35.0 in stage 1.0 (TID 83) in 40 ms on Tawfiq-PC (executor 0) (36/48)
244: 18/02/05 11:51:23 INFO TaskSetManager: Starting task 37.0 in stage 1.0 (TID 85, Tawfiq-PC, executor 0, partition 37, NODE_LOCAL, 7671 bytes)
245: 18/02/05 11:51:23 INFO TaskSetManager: Finished task 36.0 in stage 1.0 (TID 84) in 50 ms on Tawfiq-PC (executor 0) (37/48)
246: 18/02/05 11:51:23 INFO TaskSetManager: Starting task 38.0 in stage 1.0 (TID 86, Tawfiq-PC, executor 0, partition 38, NODE_LOCAL, 7671 bytes)
247: 18/02/05 11:51:23 INFO TaskSetManager: Finished task 37.0 in stage 1.0 (TID 85) in 30 ms on Tawfiq-PC (executor 0) (38/48)
248: 18/02/05 11:51:23 INFO TaskSetManager: Starting task 39.0 in stage 1.0 (TID 87, Tawfiq-PC, executor 0, partition 39, NODE_LOCAL, 7671 bytes)
249: 18/02/05 11:51:23 INFO TaskSetManager: Finished task 38.0 in stage 1.0 (TID 86) in 36 ms on Tawfiq-PC (executor 0) (39/48)
250: 18/02/05 11:51:23 INFO TaskSetManager: Starting task 40.0 in stage 1.0 (TID 88, Tawfiq-PC, executor 0, partition 40, NODE_LOCAL, 7671 bytes)
251: 18/02/05 11:51:23 INFO TaskSetManager: Finished task 39.0 in stage 1.0 (TID 87) in 36 ms on Tawfiq-PC (executor 0) (40/48)
252: 18/02/05 11:51:23 INFO TaskSetManager: Starting task 41.0 in stage 1.0 (TID 89, Tawfiq-PC, executor 0, partition 41, NODE_LOCAL, 7671 bytes)
253: 18/02/05 11:51:23 INFO TaskSetManager: Finished task 40.0 in stage 1.0 (TID 88) in 100 ms on Tawfiq-PC (executor 0) (41/48)
254: 18/02/05 11:51:23 INFO TaskSetManager: Starting task 42.0 in stage 1.0 (TID 90, Tawfiq-PC, executor 0, partition 42, NODE_LOCAL, 7671 bytes)
255: 18/02/05 11:51:23 INFO TaskSetManager: Finished task 41.0 in stage 1.0 (TID 89) in 99 ms on Tawfiq-PC (executor 0) (42/48)
256: 18/02/05 11:51:23 INFO TaskSetManager: Starting task 43.0 in stage 1.0 (TID 91, Tawfiq-PC, executor 0, partition 43, NODE_LOCAL, 7671 bytes)
257: 18/02/05 11:51:23 INFO TaskSetManager: Finished task 42.0 in stage 1.0 (TID 90) in 55 ms on Tawfiq-PC (executor 0) (43/48)
258: 18/02/05 11:51:23 INFO TaskSetManager: Starting task 44.0 in stage 1.0 (TID 92, Tawfiq-PC, executor 0, partition 44, NODE_LOCAL, 7671 bytes)
259: 18/02/05 11:51:23 INFO TaskSetManager: Finished task 43.0 in stage 1.0 (TID 91) in 31 ms on Tawfiq-PC (executor 0) (44/48)
260: 18/02/05 11:51:23 INFO TaskSetManager: Starting task 45.0 in stage 1.0 (TID 93, Tawfiq-PC, executor 0, partition 45, NODE_LOCAL, 7671 bytes)
261: 18/02/05 11:51:23 INFO TaskSetManager: Finished task 44.0 in stage 1.0 (TID 92) in 36 ms on Tawfiq-PC (executor 0) (45/48)
262: 18/02/05 11:51:23 INFO TaskSetManager: Starting task 46.0 in stage 1.0 (TID 94, Tawfiq-PC, executor 0, partition 46, NODE_LOCAL, 7671 bytes)
263: 18/02/05 11:51:23 INFO TaskSetManager: Finished task 45.0 in stage 1.0 (TID 93) in 45 ms on Tawfiq-PC (executor 0) (46/48)
264: 18/02/05 11:51:23 INFO TaskSetManager: Starting task 47.0 in stage 1.0 (TID 95, Tawfiq-PC, executor 0, partition 47, NODE_LOCAL, 7671 bytes)
265: 18/02/05 11:51:23 INFO TaskSetManager: Finished task 46.0 in stage 1.0 (TID 94) in 167 ms on Tawfiq-PC (executor 0) (47/48)
266: 18/02/05 11:51:23 INFO TaskSetManager: Finished task 47.0 in stage 1.0 (TID 95) in 94 ms on Tawfiq-PC (executor 0) (48/48)
267: 18/02/05 11:51:23 INFO TaskSchedulerImpl: Removed TaskSet 1.0, whose tasks have all completed, from pool 
268: 18/02/05 11:51:23 INFO DAGScheduler: ResultStage 1 (runJob at SparkHadoopWriter.scala:78) finished in 2.940 s
269: 18/02/05 11:51:23 INFO DAGScheduler: Job 0 finished: runJob at SparkHadoopWriter.scala:78, took 63.550961 s
270: 18/02/05 11:51:24 INFO SparkHadoopWriter: Job job_20180205115020_0005 committed.
271: 18/02/05 11:51:24 INFO SparkContext: Invoking stop() from shutdown hook
272: 18/02/05 11:51:24 INFO SparkUI: Stopped Spark web UI at http://tawfiq-pc.mobility.unimelb.net.au:4041
273: 18/02/05 11:51:24 INFO MesosCoarseGrainedSchedulerBackend: Shutting down all executors
274: 18/02/05 11:51:24 INFO CoarseGrainedSchedulerBackend$DriverEndpoint: Asking each executor to shut down
275: 18/02/05 11:51:24 INFO MesosCoarseGrainedSchedulerBackend: Mesos task 0 is now TASK_FINISHED
276: I0205 11:51:24.875365 14672 sched.cpp:2021] Asked to stop the driver
277: I0205 11:51:24.876368 14019 sched.cpp:1203] Stopping framework 2da1cbcb-6595-4749-8161-dc163a62b79d-0013
278: 18/02/05 11:51:24 INFO MesosCoarseGrainedSchedulerBackend: driver.run() returned with code DRIVER_STOPPED
279: 18/02/05 11:51:24 INFO MapOutputTrackerMasterEndpoint: MapOutputTrackerMasterEndpoint stopped!
280: 18/02/05 11:51:24 INFO MemoryStore: MemoryStore cleared
281: 18/02/05 11:51:24 INFO BlockManager: BlockManager stopped
282: 18/02/05 11:51:24 INFO BlockManagerMaster: BlockManagerMaster stopped
283: 18/02/05 11:51:24 INFO OutputCommitCoordinator$OutputCommitCoordinatorEndpoint: OutputCommitCoordinator stopped!
284: 18/02/05 11:51:24 INFO SparkContext: Successfully stopped SparkContext
285: 18/02/05 11:51:24 INFO ShutdownHookManager: Shutdown hook called
286: 18/02/05 11:51:24 INFO ShutdownHookManager: Deleting directory /tmp/spark-80d12d12-6d09-434a-b3fb-d64419eab597
287: 18/02/05 11:51:24 INFO ShutdownHookManager: Deleting directory /tmp/spark-90e8ce84-a67b-4b03-bbb2-530f1bdf20b8
