0: 18/02/05 13:03:10 WARN Utils: Your hostname, Tawfiq-PC resolves to a loopback address: 127.0.1.1; using 10.100.228.108 instead (on interface enp0s31f6)
1: 18/02/05 13:03:10 WARN Utils: Set SPARK_LOCAL_IP if you need to bind to another address
2: 18/02/05 13:03:10 WARN NativeCodeLoader: Unable to load native-hadoop library for your platform... using builtin-java classes where applicable
3: Using Spark's default log4j profile: org/apache/spark/log4j-defaults.properties
4: 18/02/05 13:03:10 INFO SparkContext: Running Spark version 2.3.0-SNAPSHOT
5: 18/02/05 13:03:10 INFO SparkContext: Submitted application: BigDataBench WordCount
6: 18/02/05 13:03:10 INFO SecurityManager: Changing view acls to: tawfiq
7: 18/02/05 13:03:10 INFO SecurityManager: Changing modify acls to: tawfiq
8: 18/02/05 13:03:10 INFO SecurityManager: Changing view acls groups to: 
9: 18/02/05 13:03:10 INFO SecurityManager: Changing modify acls groups to: 
10: 18/02/05 13:03:10 INFO SecurityManager: SecurityManager: authentication disabled; ui acls disabled; users  with view permissions: Set(tawfiq); groups with view permissions: Set(); users  with modify permissions: Set(tawfiq); groups with modify permissions: Set()
11: 18/02/05 13:03:10 INFO Utils: Successfully started service 'sparkDriver' on port 44101.
12: 18/02/05 13:03:10 INFO SparkEnv: Registering MapOutputTracker
13: 18/02/05 13:03:10 INFO SparkEnv: Registering BlockManagerMaster
14: 18/02/05 13:03:10 INFO BlockManagerMasterEndpoint: Using org.apache.spark.storage.DefaultTopologyMapper for getting topology information
15: 18/02/05 13:03:10 INFO BlockManagerMasterEndpoint: BlockManagerMasterEndpoint up
16: 18/02/05 13:03:10 INFO DiskBlockManager: Created local directory at /tmp/blockmgr-29ccf56a-375a-4a11-adfe-fe445edd138e
17: 18/02/05 13:03:10 INFO MemoryStore: MemoryStore started with capacity 366.3 MB
18: 18/02/05 13:03:10 INFO SparkEnv: Registering OutputCommitCoordinator
19: 18/02/05 13:03:10 INFO Utils: Successfully started service 'SparkUI' on port 4040.
20: 18/02/05 13:03:10 INFO SparkUI: Bound SparkUI to 0.0.0.0, and started at http://tawfiq-pc.mobility.unimelb.net.au:4040
21: 18/02/05 13:03:10 INFO SparkContext: Added JAR file:/home/tawfiq/research/spark/bigdatabench-spark_1.3.0-hadoop_1.0.4.jar at spark://tawfiq-pc.mobility.unimelb.net.au:44101/jars/bigdatabench-spark_1.3.0-hadoop_1.0.4.jar with timestamp 1517796190703
22: I0205 13:03:10.912859 17137 sched.cpp:232] Version: 1.4.0
23: I0205 13:03:10.918452 17131 sched.cpp:336] New master detected at master@127.0.0.1:5050
24: I0205 13:03:10.919695 17131 sched.cpp:352] No credentials provided. Attempting to register without authentication
25: I0205 13:03:10.931890 17128 sched.cpp:759] Framework registered with c0393525-27a6-4604-bbbb-b86657dabc56-0000
26: 18/02/05 13:03:10 INFO Utils: Successfully started service 'org.apache.spark.network.netty.NettyBlockTransferService' on port 34347.
27: 18/02/05 13:03:10 INFO NettyBlockTransferService: Server created on tawfiq-pc.mobility.unimelb.net.au:34347
28: 18/02/05 13:03:10 INFO BlockManager: Using org.apache.spark.storage.RandomBlockReplicationPolicy for block replication policy
29: 18/02/05 13:03:10 INFO BlockManagerMaster: Registering BlockManager BlockManagerId(driver, tawfiq-pc.mobility.unimelb.net.au, 34347, None)
30: 18/02/05 13:03:10 INFO BlockManagerMasterEndpoint: Registering block manager tawfiq-pc.mobility.unimelb.net.au:34347 with 366.3 MB RAM, BlockManagerId(driver, tawfiq-pc.mobility.unimelb.net.au, 34347, None)
31: 18/02/05 13:03:10 INFO BlockManagerMaster: Registered BlockManager BlockManagerId(driver, tawfiq-pc.mobility.unimelb.net.au, 34347, None)
32: 18/02/05 13:03:10 INFO BlockManager: Initialized BlockManager: BlockManagerId(driver, tawfiq-pc.mobility.unimelb.net.au, 34347, None)
33: 18/02/05 13:03:11 INFO EventLoggingListener: Logging events to file:/home/tawfiq/research/spark/logs/c0393525-27a6-4604-bbbb-b86657dabc56-0000
34: 18/02/05 13:03:11 INFO MesosCoarseGrainedSchedulerBackend: SchedulerBackend is ready for scheduling beginning after reached minRegisteredResourcesRatio: 0.0
35: 18/02/05 13:03:11 INFO MesosCoarseGrainedSchedulerBackend: Mesos task 0 is now TASK_RUNNING
36: 18/02/05 13:03:11 INFO MemoryStore: Block broadcast_0 stored as values in memory (estimated size 214.5 KB, free 366.1 MB)
37: 18/02/05 13:03:11 INFO MemoryStore: Block broadcast_0_piece0 stored as bytes in memory (estimated size 20.4 KB, free 366.1 MB)
38: 18/02/05 13:03:11 INFO BlockManagerInfo: Added broadcast_0_piece0 in memory on tawfiq-pc.mobility.unimelb.net.au:34347 (size: 20.4 KB, free: 366.3 MB)
39: 18/02/05 13:03:11 INFO SparkContext: Created broadcast 0 from textFile at WordCount.scala:26
40: 18/02/05 13:03:12 INFO FileInputFormat: Total input paths to process : 3
41: 18/02/05 13:03:12 INFO deprecation: mapred.output.dir is deprecated. Instead, use mapreduce.output.fileoutputformat.outputdir
42: 18/02/05 13:03:12 INFO SparkContext: Starting job: runJob at SparkHadoopWriter.scala:78
43: 18/02/05 13:03:12 INFO DAGScheduler: Registering RDD 3 (map at WordCount.scala:28)
44: 18/02/05 13:03:12 INFO DAGScheduler: Got job 0 (runJob at SparkHadoopWriter.scala:78) with 48 output partitions
45: 18/02/05 13:03:12 INFO DAGScheduler: Final stage: ResultStage 1 (runJob at SparkHadoopWriter.scala:78)
46: 18/02/05 13:03:12 INFO DAGScheduler: Parents of final stage: List(ShuffleMapStage 0)
47: 18/02/05 13:03:12 INFO DAGScheduler: Missing parents: List(ShuffleMapStage 0)
48: 18/02/05 13:03:12 INFO DAGScheduler: Submitting ShuffleMapStage 0 (MapPartitionsRDD[3] at map at WordCount.scala:28), which has no missing parents
49: 18/02/05 13:03:12 INFO MemoryStore: Block broadcast_1 stored as values in memory (estimated size 4.8 KB, free 366.1 MB)
50: 18/02/05 13:03:12 INFO MemoryStore: Block broadcast_1_piece0 stored as bytes in memory (estimated size 2.8 KB, free 366.1 MB)
51: 18/02/05 13:03:12 INFO BlockManagerInfo: Added broadcast_1_piece0 in memory on tawfiq-pc.mobility.unimelb.net.au:34347 (size: 2.8 KB, free: 366.3 MB)
52: 18/02/05 13:03:12 INFO SparkContext: Created broadcast 1 from broadcast at DAGScheduler.scala:1029
53: 18/02/05 13:03:12 INFO DAGScheduler: Submitting 48 missing tasks from ShuffleMapStage 0 (MapPartitionsRDD[3] at map at WordCount.scala:28) (first 15 tasks are for partitions Vector(0, 1, 2, 3, 4, 5, 6, 7, 8, 9, 10, 11, 12, 13, 14))
54: 18/02/05 13:03:12 INFO TaskSchedulerImpl: Adding task set 0.0 with 48 tasks
55: 18/02/05 13:03:13 INFO CoarseGrainedSchedulerBackend$DriverEndpoint: Registered executor NettyRpcEndpointRef(spark-client://Executor) (10.100.228.108:39450) with ID 0
56: 18/02/05 13:03:13 INFO TaskSetManager: Starting task 0.0 in stage 0.0 (TID 0, Tawfiq-PC, executor 0, partition 0, PROCESS_LOCAL, 7911 bytes)
57: 18/02/05 13:03:13 INFO BlockManagerMasterEndpoint: Registering block manager Tawfiq-PC:36161 with 912.3 MB RAM, BlockManagerId(0, Tawfiq-PC, 36161, None)
58: 18/02/05 13:03:13 INFO BlockManagerInfo: Added broadcast_1_piece0 in memory on Tawfiq-PC:36161 (size: 2.8 KB, free: 912.3 MB)
59: 18/02/05 13:03:13 INFO BlockManagerInfo: Added broadcast_0_piece0 in memory on Tawfiq-PC:36161 (size: 20.4 KB, free: 912.3 MB)
60: 18/02/05 13:03:15 INFO TaskSetManager: Starting task 1.0 in stage 0.0 (TID 1, Tawfiq-PC, executor 0, partition 1, PROCESS_LOCAL, 7911 bytes)
61: 18/02/05 13:03:15 INFO TaskSetManager: Finished task 0.0 in stage 0.0 (TID 0) in 2161 ms on Tawfiq-PC (executor 0) (1/48)
62: 18/02/05 13:03:16 INFO TaskSetManager: Starting task 2.0 in stage 0.0 (TID 2, Tawfiq-PC, executor 0, partition 2, PROCESS_LOCAL, 7911 bytes)
63: 18/02/05 13:03:16 INFO TaskSetManager: Finished task 1.0 in stage 0.0 (TID 1) in 844 ms on Tawfiq-PC (executor 0) (2/48)
64: 18/02/05 13:03:17 INFO TaskSetManager: Starting task 3.0 in stage 0.0 (TID 3, Tawfiq-PC, executor 0, partition 3, PROCESS_LOCAL, 7911 bytes)
65: 18/02/05 13:03:17 INFO TaskSetManager: Finished task 2.0 in stage 0.0 (TID 2) in 738 ms on Tawfiq-PC (executor 0) (3/48)
66: 18/02/05 13:03:17 INFO TaskSetManager: Starting task 4.0 in stage 0.0 (TID 4, Tawfiq-PC, executor 0, partition 4, PROCESS_LOCAL, 7911 bytes)
67: 18/02/05 13:03:17 INFO TaskSetManager: Finished task 3.0 in stage 0.0 (TID 3) in 723 ms on Tawfiq-PC (executor 0) (4/48)
68: 18/02/05 13:03:18 INFO TaskSetManager: Starting task 5.0 in stage 0.0 (TID 5, Tawfiq-PC, executor 0, partition 5, PROCESS_LOCAL, 7911 bytes)
69: 18/02/05 13:03:18 INFO TaskSetManager: Finished task 4.0 in stage 0.0 (TID 4) in 790 ms on Tawfiq-PC (executor 0) (5/48)
70: 18/02/05 13:03:19 INFO TaskSetManager: Starting task 6.0 in stage 0.0 (TID 6, Tawfiq-PC, executor 0, partition 6, PROCESS_LOCAL, 7911 bytes)
71: 18/02/05 13:03:19 INFO TaskSetManager: Finished task 5.0 in stage 0.0 (TID 5) in 761 ms on Tawfiq-PC (executor 0) (6/48)
72: 18/02/05 13:03:20 INFO TaskSetManager: Starting task 7.0 in stage 0.0 (TID 7, Tawfiq-PC, executor 0, partition 7, PROCESS_LOCAL, 7911 bytes)
73: 18/02/05 13:03:20 INFO TaskSetManager: Finished task 6.0 in stage 0.0 (TID 6) in 737 ms on Tawfiq-PC (executor 0) (7/48)
74: 18/02/05 13:03:20 INFO TaskSetManager: Starting task 8.0 in stage 0.0 (TID 8, Tawfiq-PC, executor 0, partition 8, PROCESS_LOCAL, 7911 bytes)
75: 18/02/05 13:03:20 INFO TaskSetManager: Finished task 7.0 in stage 0.0 (TID 7) in 763 ms on Tawfiq-PC (executor 0) (8/48)
76: 18/02/05 13:03:21 INFO TaskSetManager: Starting task 9.0 in stage 0.0 (TID 9, Tawfiq-PC, executor 0, partition 9, PROCESS_LOCAL, 7911 bytes)
77: 18/02/05 13:03:21 INFO TaskSetManager: Finished task 8.0 in stage 0.0 (TID 8) in 732 ms on Tawfiq-PC (executor 0) (9/48)
78: 18/02/05 13:03:22 INFO TaskSetManager: Starting task 10.0 in stage 0.0 (TID 10, Tawfiq-PC, executor 0, partition 10, PROCESS_LOCAL, 7911 bytes)
79: 18/02/05 13:03:22 INFO TaskSetManager: Finished task 9.0 in stage 0.0 (TID 9) in 793 ms on Tawfiq-PC (executor 0) (10/48)
80: 18/02/05 13:03:23 INFO TaskSetManager: Starting task 11.0 in stage 0.0 (TID 11, Tawfiq-PC, executor 0, partition 11, PROCESS_LOCAL, 7911 bytes)
81: 18/02/05 13:03:23 INFO TaskSetManager: Finished task 10.0 in stage 0.0 (TID 10) in 794 ms on Tawfiq-PC (executor 0) (11/48)
82: 18/02/05 13:03:24 INFO TaskSetManager: Starting task 12.0 in stage 0.0 (TID 12, Tawfiq-PC, executor 0, partition 12, PROCESS_LOCAL, 7911 bytes)
83: 18/02/05 13:03:24 INFO TaskSetManager: Finished task 11.0 in stage 0.0 (TID 11) in 895 ms on Tawfiq-PC (executor 0) (12/48)
84: 18/02/05 13:03:24 INFO TaskSetManager: Starting task 13.0 in stage 0.0 (TID 13, Tawfiq-PC, executor 0, partition 13, PROCESS_LOCAL, 7911 bytes)
85: 18/02/05 13:03:24 INFO TaskSetManager: Finished task 12.0 in stage 0.0 (TID 12) in 811 ms on Tawfiq-PC (executor 0) (13/48)
86: 18/02/05 13:03:25 INFO TaskSetManager: Starting task 14.0 in stage 0.0 (TID 14, Tawfiq-PC, executor 0, partition 14, PROCESS_LOCAL, 7911 bytes)
87: 18/02/05 13:03:25 INFO TaskSetManager: Finished task 13.0 in stage 0.0 (TID 13) in 782 ms on Tawfiq-PC (executor 0) (14/48)
88: 18/02/05 13:03:26 INFO TaskSetManager: Starting task 15.0 in stage 0.0 (TID 15, Tawfiq-PC, executor 0, partition 15, PROCESS_LOCAL, 7911 bytes)
89: 18/02/05 13:03:26 INFO TaskSetManager: Finished task 14.0 in stage 0.0 (TID 14) in 748 ms on Tawfiq-PC (executor 0) (15/48)
90: 18/02/05 13:03:26 INFO TaskSetManager: Starting task 16.0 in stage 0.0 (TID 16, Tawfiq-PC, executor 0, partition 16, PROCESS_LOCAL, 7907 bytes)
91: 18/02/05 13:03:26 INFO TaskSetManager: Finished task 15.0 in stage 0.0 (TID 15) in 497 ms on Tawfiq-PC (executor 0) (16/48)
92: 18/02/05 13:03:27 INFO TaskSetManager: Starting task 17.0 in stage 0.0 (TID 17, Tawfiq-PC, executor 0, partition 17, PROCESS_LOCAL, 7907 bytes)
93: 18/02/05 13:03:27 INFO TaskSetManager: Finished task 16.0 in stage 0.0 (TID 16) in 736 ms on Tawfiq-PC (executor 0) (17/48)
94: 18/02/05 13:03:28 INFO TaskSetManager: Starting task 18.0 in stage 0.0 (TID 18, Tawfiq-PC, executor 0, partition 18, PROCESS_LOCAL, 7907 bytes)
95: 18/02/05 13:03:28 INFO TaskSetManager: Finished task 17.0 in stage 0.0 (TID 17) in 739 ms on Tawfiq-PC (executor 0) (18/48)
96: 18/02/05 13:03:29 INFO TaskSetManager: Starting task 19.0 in stage 0.0 (TID 19, Tawfiq-PC, executor 0, partition 19, PROCESS_LOCAL, 7907 bytes)
97: 18/02/05 13:03:29 INFO TaskSetManager: Finished task 18.0 in stage 0.0 (TID 18) in 762 ms on Tawfiq-PC (executor 0) (19/48)
98: 18/02/05 13:03:29 INFO TaskSetManager: Starting task 20.0 in stage 0.0 (TID 20, Tawfiq-PC, executor 0, partition 20, PROCESS_LOCAL, 7907 bytes)
99: 18/02/05 13:03:29 INFO TaskSetManager: Finished task 19.0 in stage 0.0 (TID 19) in 813 ms on Tawfiq-PC (executor 0) (20/48)
100: 18/02/05 13:03:30 INFO TaskSetManager: Starting task 21.0 in stage 0.0 (TID 21, Tawfiq-PC, executor 0, partition 21, PROCESS_LOCAL, 7907 bytes)
101: 18/02/05 13:03:30 INFO TaskSetManager: Finished task 20.0 in stage 0.0 (TID 20) in 754 ms on Tawfiq-PC (executor 0) (21/48)
102: 18/02/05 13:03:31 INFO TaskSetManager: Starting task 22.0 in stage 0.0 (TID 22, Tawfiq-PC, executor 0, partition 22, PROCESS_LOCAL, 7907 bytes)
103: 18/02/05 13:03:31 INFO TaskSetManager: Finished task 21.0 in stage 0.0 (TID 21) in 745 ms on Tawfiq-PC (executor 0) (22/48)
104: 18/02/05 13:03:32 INFO TaskSetManager: Starting task 23.0 in stage 0.0 (TID 23, Tawfiq-PC, executor 0, partition 23, PROCESS_LOCAL, 7907 bytes)
105: 18/02/05 13:03:32 INFO TaskSetManager: Finished task 22.0 in stage 0.0 (TID 22) in 712 ms on Tawfiq-PC (executor 0) (23/48)
106: 18/02/05 13:03:32 INFO TaskSetManager: Starting task 24.0 in stage 0.0 (TID 24, Tawfiq-PC, executor 0, partition 24, PROCESS_LOCAL, 7907 bytes)
107: 18/02/05 13:03:32 INFO TaskSetManager: Finished task 23.0 in stage 0.0 (TID 23) in 766 ms on Tawfiq-PC (executor 0) (24/48)
108: 18/02/05 13:03:33 INFO TaskSetManager: Starting task 25.0 in stage 0.0 (TID 25, Tawfiq-PC, executor 0, partition 25, PROCESS_LOCAL, 7907 bytes)
109: 18/02/05 13:03:33 INFO TaskSetManager: Finished task 24.0 in stage 0.0 (TID 24) in 758 ms on Tawfiq-PC (executor 0) (25/48)
110: 18/02/05 13:03:34 INFO TaskSetManager: Starting task 26.0 in stage 0.0 (TID 26, Tawfiq-PC, executor 0, partition 26, PROCESS_LOCAL, 7907 bytes)
111: 18/02/05 13:03:34 INFO TaskSetManager: Finished task 25.0 in stage 0.0 (TID 25) in 773 ms on Tawfiq-PC (executor 0) (26/48)
112: 18/02/05 13:03:35 INFO TaskSetManager: Starting task 27.0 in stage 0.0 (TID 27, Tawfiq-PC, executor 0, partition 27, PROCESS_LOCAL, 7907 bytes)
113: 18/02/05 13:03:35 INFO TaskSetManager: Finished task 26.0 in stage 0.0 (TID 26) in 821 ms on Tawfiq-PC (executor 0) (27/48)
114: 18/02/05 13:03:35 INFO TaskSetManager: Starting task 28.0 in stage 0.0 (TID 28, Tawfiq-PC, executor 0, partition 28, PROCESS_LOCAL, 7907 bytes)
115: 18/02/05 13:03:35 INFO TaskSetManager: Finished task 27.0 in stage 0.0 (TID 27) in 729 ms on Tawfiq-PC (executor 0) (28/48)
116: 18/02/05 13:03:36 INFO TaskSetManager: Starting task 29.0 in stage 0.0 (TID 29, Tawfiq-PC, executor 0, partition 29, PROCESS_LOCAL, 7907 bytes)
117: 18/02/05 13:03:36 INFO TaskSetManager: Finished task 28.0 in stage 0.0 (TID 28) in 863 ms on Tawfiq-PC (executor 0) (29/48)
118: 18/02/05 13:03:37 INFO TaskSetManager: Starting task 30.0 in stage 0.0 (TID 30, Tawfiq-PC, executor 0, partition 30, PROCESS_LOCAL, 7907 bytes)
119: 18/02/05 13:03:37 INFO TaskSetManager: Finished task 29.0 in stage 0.0 (TID 29) in 754 ms on Tawfiq-PC (executor 0) (30/48)
120: 18/02/05 13:03:38 INFO TaskSetManager: Starting task 31.0 in stage 0.0 (TID 31, Tawfiq-PC, executor 0, partition 31, PROCESS_LOCAL, 7907 bytes)
121: 18/02/05 13:03:38 INFO TaskSetManager: Finished task 30.0 in stage 0.0 (TID 30) in 740 ms on Tawfiq-PC (executor 0) (31/48)
122: 18/02/05 13:03:38 INFO TaskSetManager: Starting task 32.0 in stage 0.0 (TID 32, Tawfiq-PC, executor 0, partition 32, PROCESS_LOCAL, 7900 bytes)
123: 18/02/05 13:03:38 INFO TaskSetManager: Finished task 31.0 in stage 0.0 (TID 31) in 502 ms on Tawfiq-PC (executor 0) (32/48)
124: 18/02/05 13:03:39 INFO TaskSetManager: Starting task 33.0 in stage 0.0 (TID 33, Tawfiq-PC, executor 0, partition 33, PROCESS_LOCAL, 7900 bytes)
125: 18/02/05 13:03:39 INFO TaskSetManager: Finished task 32.0 in stage 0.0 (TID 32) in 765 ms on Tawfiq-PC (executor 0) (33/48)
126: 18/02/05 13:03:40 INFO TaskSetManager: Starting task 34.0 in stage 0.0 (TID 34, Tawfiq-PC, executor 0, partition 34, PROCESS_LOCAL, 7900 bytes)
127: 18/02/05 13:03:40 INFO TaskSetManager: Finished task 33.0 in stage 0.0 (TID 33) in 733 ms on Tawfiq-PC (executor 0) (34/48)
128: 18/02/05 13:03:41 INFO TaskSetManager: Starting task 35.0 in stage 0.0 (TID 35, Tawfiq-PC, executor 0, partition 35, PROCESS_LOCAL, 7900 bytes)
129: 18/02/05 13:03:41 INFO TaskSetManager: Finished task 34.0 in stage 0.0 (TID 34) in 704 ms on Tawfiq-PC (executor 0) (35/48)
130: 18/02/05 13:03:41 INFO TaskSetManager: Starting task 36.0 in stage 0.0 (TID 36, Tawfiq-PC, executor 0, partition 36, PROCESS_LOCAL, 7900 bytes)
131: 18/02/05 13:03:41 INFO TaskSetManager: Finished task 35.0 in stage 0.0 (TID 35) in 764 ms on Tawfiq-PC (executor 0) (36/48)
132: 18/02/05 13:03:42 INFO TaskSetManager: Starting task 37.0 in stage 0.0 (TID 37, Tawfiq-PC, executor 0, partition 37, PROCESS_LOCAL, 7900 bytes)
133: 18/02/05 13:03:42 INFO TaskSetManager: Finished task 36.0 in stage 0.0 (TID 36) in 844 ms on Tawfiq-PC (executor 0) (37/48)
134: 18/02/05 13:03:43 INFO TaskSetManager: Starting task 38.0 in stage 0.0 (TID 38, Tawfiq-PC, executor 0, partition 38, PROCESS_LOCAL, 7900 bytes)
135: 18/02/05 13:03:43 INFO TaskSetManager: Finished task 37.0 in stage 0.0 (TID 37) in 749 ms on Tawfiq-PC (executor 0) (38/48)
136: 18/02/05 13:03:44 INFO TaskSetManager: Starting task 39.0 in stage 0.0 (TID 39, Tawfiq-PC, executor 0, partition 39, PROCESS_LOCAL, 7900 bytes)
137: 18/02/05 13:03:44 INFO TaskSetManager: Finished task 38.0 in stage 0.0 (TID 38) in 733 ms on Tawfiq-PC (executor 0) (39/48)
138: 18/02/05 13:03:44 INFO TaskSetManager: Starting task 40.0 in stage 0.0 (TID 40, Tawfiq-PC, executor 0, partition 40, PROCESS_LOCAL, 7900 bytes)
139: 18/02/05 13:03:44 INFO TaskSetManager: Finished task 39.0 in stage 0.0 (TID 39) in 755 ms on Tawfiq-PC (executor 0) (40/48)
140: 18/02/05 13:03:45 INFO TaskSetManager: Starting task 41.0 in stage 0.0 (TID 41, Tawfiq-PC, executor 0, partition 41, PROCESS_LOCAL, 7900 bytes)
141: 18/02/05 13:03:45 INFO TaskSetManager: Finished task 40.0 in stage 0.0 (TID 40) in 755 ms on Tawfiq-PC (executor 0) (41/48)
142: 18/02/05 13:03:46 INFO TaskSetManager: Starting task 42.0 in stage 0.0 (TID 42, Tawfiq-PC, executor 0, partition 42, PROCESS_LOCAL, 7900 bytes)
143: 18/02/05 13:03:46 INFO TaskSetManager: Finished task 41.0 in stage 0.0 (TID 41) in 756 ms on Tawfiq-PC (executor 0) (42/48)
144: 18/02/05 13:03:47 INFO TaskSetManager: Starting task 43.0 in stage 0.0 (TID 43, Tawfiq-PC, executor 0, partition 43, PROCESS_LOCAL, 7900 bytes)
145: 18/02/05 13:03:47 INFO TaskSetManager: Finished task 42.0 in stage 0.0 (TID 42) in 752 ms on Tawfiq-PC (executor 0) (43/48)
146: 18/02/05 13:03:47 INFO TaskSetManager: Starting task 44.0 in stage 0.0 (TID 44, Tawfiq-PC, executor 0, partition 44, PROCESS_LOCAL, 7900 bytes)
147: 18/02/05 13:03:47 INFO TaskSetManager: Finished task 43.0 in stage 0.0 (TID 43) in 728 ms on Tawfiq-PC (executor 0) (44/48)
148: 18/02/05 13:03:48 INFO TaskSetManager: Starting task 45.0 in stage 0.0 (TID 45, Tawfiq-PC, executor 0, partition 45, PROCESS_LOCAL, 7900 bytes)
149: 18/02/05 13:03:48 INFO TaskSetManager: Finished task 44.0 in stage 0.0 (TID 44) in 710 ms on Tawfiq-PC (executor 0) (45/48)
150: 18/02/05 13:03:49 INFO TaskSetManager: Starting task 46.0 in stage 0.0 (TID 46, Tawfiq-PC, executor 0, partition 46, PROCESS_LOCAL, 7900 bytes)
151: 18/02/05 13:03:49 INFO TaskSetManager: Finished task 45.0 in stage 0.0 (TID 45) in 779 ms on Tawfiq-PC (executor 0) (46/48)
152: 18/02/05 13:03:50 INFO TaskSetManager: Starting task 47.0 in stage 0.0 (TID 47, Tawfiq-PC, executor 0, partition 47, PROCESS_LOCAL, 7900 bytes)
153: 18/02/05 13:03:50 INFO TaskSetManager: Finished task 46.0 in stage 0.0 (TID 46) in 767 ms on Tawfiq-PC (executor 0) (47/48)
154: 18/02/05 13:03:50 INFO TaskSetManager: Finished task 47.0 in stage 0.0 (TID 47) in 521 ms on Tawfiq-PC (executor 0) (48/48)
155: 18/02/05 13:03:50 INFO TaskSchedulerImpl: Removed TaskSet 0.0, whose tasks have all completed, from pool 
156: 18/02/05 13:03:50 INFO DAGScheduler: ShuffleMapStage 0 (map at WordCount.scala:28) finished in 38.303 s
157: 18/02/05 13:03:50 INFO DAGScheduler: looking for newly runnable stages
158: 18/02/05 13:03:50 INFO DAGScheduler: running: Set()
159: 18/02/05 13:03:50 INFO DAGScheduler: waiting: Set(ResultStage 1)
160: 18/02/05 13:03:50 INFO DAGScheduler: failed: Set()
161: 18/02/05 13:03:50 INFO DAGScheduler: Submitting ResultStage 1 (MapPartitionsRDD[5] at saveAsTextFile at WordCount.scala:31), which has no missing parents
162: 18/02/05 13:03:50 INFO MemoryStore: Block broadcast_2 stored as values in memory (estimated size 65.6 KB, free 366.0 MB)
163: 18/02/05 13:03:50 INFO MemoryStore: Block broadcast_2_piece0 stored as bytes in memory (estimated size 23.6 KB, free 366.0 MB)
164: 18/02/05 13:03:50 INFO BlockManagerInfo: Added broadcast_2_piece0 in memory on tawfiq-pc.mobility.unimelb.net.au:34347 (size: 23.6 KB, free: 366.3 MB)
165: 18/02/05 13:03:50 INFO SparkContext: Created broadcast 2 from broadcast at DAGScheduler.scala:1029
166: 18/02/05 13:03:50 INFO DAGScheduler: Submitting 48 missing tasks from ResultStage 1 (MapPartitionsRDD[5] at saveAsTextFile at WordCount.scala:31) (first 15 tasks are for partitions Vector(0, 1, 2, 3, 4, 5, 6, 7, 8, 9, 10, 11, 12, 13, 14))
167: 18/02/05 13:03:50 INFO TaskSchedulerImpl: Adding task set 1.0 with 48 tasks
168: 18/02/05 13:03:50 INFO TaskSetManager: Starting task 0.0 in stage 1.0 (TID 48, Tawfiq-PC, executor 0, partition 0, NODE_LOCAL, 7671 bytes)
169: 18/02/05 13:03:50 INFO BlockManagerInfo: Added broadcast_2_piece0 in memory on Tawfiq-PC:36161 (size: 23.6 KB, free: 912.3 MB)
170: 18/02/05 13:03:50 INFO MapOutputTrackerMasterEndpoint: Asked to send map output locations for shuffle 0 to 10.100.228.108:39450
171: 18/02/05 13:03:50 INFO BlockManagerInfo: Removed broadcast_1_piece0 on Tawfiq-PC:36161 in memory (size: 2.8 KB, free: 912.3 MB)
172: 18/02/05 13:03:50 INFO BlockManagerInfo: Removed broadcast_1_piece0 on tawfiq-pc.mobility.unimelb.net.au:34347 in memory (size: 2.8 KB, free: 366.3 MB)
173: 18/02/05 13:03:50 INFO TaskSetManager: Starting task 1.0 in stage 1.0 (TID 49, Tawfiq-PC, executor 0, partition 1, NODE_LOCAL, 7671 bytes)
174: 18/02/05 13:03:50 INFO TaskSetManager: Finished task 0.0 in stage 1.0 (TID 48) in 227 ms on Tawfiq-PC (executor 0) (1/48)
175: 18/02/05 13:03:50 INFO TaskSetManager: Starting task 2.0 in stage 1.0 (TID 50, Tawfiq-PC, executor 0, partition 2, NODE_LOCAL, 7671 bytes)
176: 18/02/05 13:03:50 INFO TaskSetManager: Finished task 1.0 in stage 1.0 (TID 49) in 83 ms on Tawfiq-PC (executor 0) (2/48)
177: 18/02/05 13:03:51 INFO TaskSetManager: Starting task 3.0 in stage 1.0 (TID 51, Tawfiq-PC, executor 0, partition 3, NODE_LOCAL, 7671 bytes)
178: 18/02/05 13:03:51 INFO TaskSetManager: Finished task 2.0 in stage 1.0 (TID 50) in 50 ms on Tawfiq-PC (executor 0) (3/48)
179: 18/02/05 13:03:51 INFO TaskSetManager: Starting task 4.0 in stage 1.0 (TID 52, Tawfiq-PC, executor 0, partition 4, NODE_LOCAL, 7671 bytes)
180: 18/02/05 13:03:51 INFO TaskSetManager: Finished task 3.0 in stage 1.0 (TID 51) in 51 ms on Tawfiq-PC (executor 0) (4/48)
181: 18/02/05 13:03:51 INFO TaskSetManager: Starting task 5.0 in stage 1.0 (TID 53, Tawfiq-PC, executor 0, partition 5, NODE_LOCAL, 7671 bytes)
182: 18/02/05 13:03:51 INFO TaskSetManager: Finished task 4.0 in stage 1.0 (TID 52) in 73 ms on Tawfiq-PC (executor 0) (5/48)
183: 18/02/05 13:03:51 INFO TaskSetManager: Starting task 6.0 in stage 1.0 (TID 54, Tawfiq-PC, executor 0, partition 6, NODE_LOCAL, 7671 bytes)
184: 18/02/05 13:03:51 INFO TaskSetManager: Finished task 5.0 in stage 1.0 (TID 53) in 50 ms on Tawfiq-PC (executor 0) (6/48)
185: 18/02/05 13:03:51 INFO TaskSetManager: Starting task 7.0 in stage 1.0 (TID 55, Tawfiq-PC, executor 0, partition 7, NODE_LOCAL, 7671 bytes)
186: 18/02/05 13:03:51 INFO TaskSetManager: Finished task 6.0 in stage 1.0 (TID 54) in 53 ms on Tawfiq-PC (executor 0) (7/48)
187: 18/02/05 13:03:51 INFO TaskSetManager: Starting task 8.0 in stage 1.0 (TID 56, Tawfiq-PC, executor 0, partition 8, NODE_LOCAL, 7671 bytes)
188: 18/02/05 13:03:51 INFO TaskSetManager: Finished task 7.0 in stage 1.0 (TID 55) in 39 ms on Tawfiq-PC (executor 0) (8/48)
189: 18/02/05 13:03:51 INFO TaskSetManager: Starting task 9.0 in stage 1.0 (TID 57, Tawfiq-PC, executor 0, partition 9, NODE_LOCAL, 7671 bytes)
190: 18/02/05 13:03:51 INFO TaskSetManager: Finished task 8.0 in stage 1.0 (TID 56) in 35 ms on Tawfiq-PC (executor 0) (9/48)
191: 18/02/05 13:03:51 INFO TaskSetManager: Starting task 10.0 in stage 1.0 (TID 58, Tawfiq-PC, executor 0, partition 10, NODE_LOCAL, 7671 bytes)
192: 18/02/05 13:03:51 INFO TaskSetManager: Finished task 9.0 in stage 1.0 (TID 57) in 36 ms on Tawfiq-PC (executor 0) (10/48)
193: 18/02/05 13:03:51 INFO TaskSetManager: Starting task 11.0 in stage 1.0 (TID 59, Tawfiq-PC, executor 0, partition 11, NODE_LOCAL, 7671 bytes)
194: 18/02/05 13:03:51 INFO TaskSetManager: Finished task 10.0 in stage 1.0 (TID 58) in 49 ms on Tawfiq-PC (executor 0) (11/48)
195: 18/02/05 13:03:51 INFO TaskSetManager: Starting task 12.0 in stage 1.0 (TID 60, Tawfiq-PC, executor 0, partition 12, NODE_LOCAL, 7671 bytes)
196: 18/02/05 13:03:51 INFO TaskSetManager: Finished task 11.0 in stage 1.0 (TID 59) in 55 ms on Tawfiq-PC (executor 0) (12/48)
197: 18/02/05 13:03:51 INFO TaskSetManager: Starting task 13.0 in stage 1.0 (TID 61, Tawfiq-PC, executor 0, partition 13, NODE_LOCAL, 7671 bytes)
198: 18/02/05 13:03:51 INFO TaskSetManager: Finished task 12.0 in stage 1.0 (TID 60) in 48 ms on Tawfiq-PC (executor 0) (13/48)
199: 18/02/05 13:03:51 INFO TaskSetManager: Starting task 14.0 in stage 1.0 (TID 62, Tawfiq-PC, executor 0, partition 14, NODE_LOCAL, 7671 bytes)
200: 18/02/05 13:03:51 INFO TaskSetManager: Finished task 13.0 in stage 1.0 (TID 61) in 58 ms on Tawfiq-PC (executor 0) (14/48)
201: 18/02/05 13:03:51 INFO TaskSetManager: Starting task 15.0 in stage 1.0 (TID 63, Tawfiq-PC, executor 0, partition 15, NODE_LOCAL, 7671 bytes)
202: 18/02/05 13:03:51 INFO TaskSetManager: Finished task 14.0 in stage 1.0 (TID 62) in 49 ms on Tawfiq-PC (executor 0) (15/48)
203: 18/02/05 13:03:51 INFO TaskSetManager: Starting task 16.0 in stage 1.0 (TID 64, Tawfiq-PC, executor 0, partition 16, NODE_LOCAL, 7671 bytes)
204: 18/02/05 13:03:51 INFO TaskSetManager: Finished task 15.0 in stage 1.0 (TID 63) in 56 ms on Tawfiq-PC (executor 0) (16/48)
205: 18/02/05 13:03:51 INFO TaskSetManager: Starting task 17.0 in stage 1.0 (TID 65, Tawfiq-PC, executor 0, partition 17, NODE_LOCAL, 7671 bytes)
206: 18/02/05 13:03:51 INFO TaskSetManager: Finished task 16.0 in stage 1.0 (TID 64) in 34 ms on Tawfiq-PC (executor 0) (17/48)
207: 18/02/05 13:03:51 INFO TaskSetManager: Starting task 18.0 in stage 1.0 (TID 66, Tawfiq-PC, executor 0, partition 18, NODE_LOCAL, 7671 bytes)
208: 18/02/05 13:03:51 INFO TaskSetManager: Finished task 17.0 in stage 1.0 (TID 65) in 48 ms on Tawfiq-PC (executor 0) (18/48)
209: 18/02/05 13:03:51 INFO TaskSetManager: Starting task 19.0 in stage 1.0 (TID 67, Tawfiq-PC, executor 0, partition 19, NODE_LOCAL, 7671 bytes)
210: 18/02/05 13:03:51 INFO TaskSetManager: Finished task 18.0 in stage 1.0 (TID 66) in 45 ms on Tawfiq-PC (executor 0) (19/48)
211: 18/02/05 13:03:51 INFO TaskSetManager: Starting task 20.0 in stage 1.0 (TID 68, Tawfiq-PC, executor 0, partition 20, NODE_LOCAL, 7671 bytes)
212: 18/02/05 13:03:51 INFO TaskSetManager: Finished task 19.0 in stage 1.0 (TID 67) in 45 ms on Tawfiq-PC (executor 0) (20/48)
213: 18/02/05 13:03:51 INFO TaskSetManager: Starting task 21.0 in stage 1.0 (TID 69, Tawfiq-PC, executor 0, partition 21, NODE_LOCAL, 7671 bytes)
214: 18/02/05 13:03:51 INFO TaskSetManager: Finished task 20.0 in stage 1.0 (TID 68) in 42 ms on Tawfiq-PC (executor 0) (21/48)
215: 18/02/05 13:03:51 INFO TaskSetManager: Starting task 22.0 in stage 1.0 (TID 70, Tawfiq-PC, executor 0, partition 22, NODE_LOCAL, 7671 bytes)
216: 18/02/05 13:03:51 INFO TaskSetManager: Finished task 21.0 in stage 1.0 (TID 69) in 38 ms on Tawfiq-PC (executor 0) (22/48)
217: 18/02/05 13:03:51 INFO TaskSetManager: Starting task 23.0 in stage 1.0 (TID 71, Tawfiq-PC, executor 0, partition 23, NODE_LOCAL, 7671 bytes)
218: 18/02/05 13:03:51 INFO TaskSetManager: Finished task 22.0 in stage 1.0 (TID 70) in 49 ms on Tawfiq-PC (executor 0) (23/48)
219: 18/02/05 13:03:52 INFO TaskSetManager: Starting task 24.0 in stage 1.0 (TID 72, Tawfiq-PC, executor 0, partition 24, NODE_LOCAL, 7671 bytes)
220: 18/02/05 13:03:52 INFO TaskSetManager: Finished task 23.0 in stage 1.0 (TID 71) in 33 ms on Tawfiq-PC (executor 0) (24/48)
221: 18/02/05 13:03:52 INFO TaskSetManager: Starting task 25.0 in stage 1.0 (TID 73, Tawfiq-PC, executor 0, partition 25, NODE_LOCAL, 7671 bytes)
222: 18/02/05 13:03:52 INFO TaskSetManager: Finished task 24.0 in stage 1.0 (TID 72) in 35 ms on Tawfiq-PC (executor 0) (25/48)
223: 18/02/05 13:03:52 INFO TaskSetManager: Starting task 26.0 in stage 1.0 (TID 74, Tawfiq-PC, executor 0, partition 26, NODE_LOCAL, 7671 bytes)
224: 18/02/05 13:03:52 INFO TaskSetManager: Finished task 25.0 in stage 1.0 (TID 73) in 30 ms on Tawfiq-PC (executor 0) (26/48)
225: 18/02/05 13:03:52 INFO TaskSetManager: Starting task 27.0 in stage 1.0 (TID 75, Tawfiq-PC, executor 0, partition 27, NODE_LOCAL, 7671 bytes)
226: 18/02/05 13:03:52 INFO TaskSetManager: Finished task 26.0 in stage 1.0 (TID 74) in 32 ms on Tawfiq-PC (executor 0) (27/48)
227: 18/02/05 13:03:52 INFO TaskSetManager: Starting task 28.0 in stage 1.0 (TID 76, Tawfiq-PC, executor 0, partition 28, NODE_LOCAL, 7671 bytes)
228: 18/02/05 13:03:52 INFO TaskSetManager: Finished task 27.0 in stage 1.0 (TID 75) in 33 ms on Tawfiq-PC (executor 0) (28/48)
229: 18/02/05 13:03:52 INFO TaskSetManager: Starting task 29.0 in stage 1.0 (TID 77, Tawfiq-PC, executor 0, partition 29, NODE_LOCAL, 7671 bytes)
230: 18/02/05 13:03:52 INFO TaskSetManager: Finished task 28.0 in stage 1.0 (TID 76) in 61 ms on Tawfiq-PC (executor 0) (29/48)
231: 18/02/05 13:03:52 INFO TaskSetManager: Starting task 30.0 in stage 1.0 (TID 78, Tawfiq-PC, executor 0, partition 30, NODE_LOCAL, 7671 bytes)
232: 18/02/05 13:03:52 INFO TaskSetManager: Finished task 29.0 in stage 1.0 (TID 77) in 51 ms on Tawfiq-PC (executor 0) (30/48)
233: 18/02/05 13:03:52 INFO TaskSetManager: Starting task 31.0 in stage 1.0 (TID 79, Tawfiq-PC, executor 0, partition 31, NODE_LOCAL, 7671 bytes)
234: 18/02/05 13:03:52 INFO TaskSetManager: Finished task 30.0 in stage 1.0 (TID 78) in 47 ms on Tawfiq-PC (executor 0) (31/48)
235: 18/02/05 13:03:52 INFO TaskSetManager: Starting task 32.0 in stage 1.0 (TID 80, Tawfiq-PC, executor 0, partition 32, NODE_LOCAL, 7671 bytes)
236: 18/02/05 13:03:52 INFO TaskSetManager: Finished task 31.0 in stage 1.0 (TID 79) in 30 ms on Tawfiq-PC (executor 0) (32/48)
237: 18/02/05 13:03:52 INFO TaskSetManager: Starting task 33.0 in stage 1.0 (TID 81, Tawfiq-PC, executor 0, partition 33, NODE_LOCAL, 7671 bytes)
238: 18/02/05 13:03:52 INFO TaskSetManager: Finished task 32.0 in stage 1.0 (TID 80) in 32 ms on Tawfiq-PC (executor 0) (33/48)
239: 18/02/05 13:03:52 INFO TaskSetManager: Starting task 34.0 in stage 1.0 (TID 82, Tawfiq-PC, executor 0, partition 34, NODE_LOCAL, 7671 bytes)
240: 18/02/05 13:03:52 INFO TaskSetManager: Finished task 33.0 in stage 1.0 (TID 81) in 33 ms on Tawfiq-PC (executor 0) (34/48)
241: 18/02/05 13:03:52 INFO TaskSetManager: Starting task 35.0 in stage 1.0 (TID 83, Tawfiq-PC, executor 0, partition 35, NODE_LOCAL, 7671 bytes)
242: 18/02/05 13:03:52 INFO TaskSetManager: Finished task 34.0 in stage 1.0 (TID 82) in 33 ms on Tawfiq-PC (executor 0) (35/48)
243: 18/02/05 13:03:52 INFO TaskSetManager: Starting task 36.0 in stage 1.0 (TID 84, Tawfiq-PC, executor 0, partition 36, NODE_LOCAL, 7671 bytes)
244: 18/02/05 13:03:52 INFO TaskSetManager: Finished task 35.0 in stage 1.0 (TID 83) in 33 ms on Tawfiq-PC (executor 0) (36/48)
245: 18/02/05 13:03:52 INFO TaskSetManager: Starting task 37.0 in stage 1.0 (TID 85, Tawfiq-PC, executor 0, partition 37, NODE_LOCAL, 7671 bytes)
246: 18/02/05 13:03:52 INFO TaskSetManager: Finished task 36.0 in stage 1.0 (TID 84) in 32 ms on Tawfiq-PC (executor 0) (37/48)
247: 18/02/05 13:03:52 INFO TaskSetManager: Starting task 38.0 in stage 1.0 (TID 86, Tawfiq-PC, executor 0, partition 38, NODE_LOCAL, 7671 bytes)
248: 18/02/05 13:03:52 INFO TaskSetManager: Finished task 37.0 in stage 1.0 (TID 85) in 31 ms on Tawfiq-PC (executor 0) (38/48)
249: 18/02/05 13:03:52 INFO TaskSetManager: Starting task 39.0 in stage 1.0 (TID 87, Tawfiq-PC, executor 0, partition 39, NODE_LOCAL, 7671 bytes)
250: 18/02/05 13:03:52 INFO TaskSetManager: Finished task 38.0 in stage 1.0 (TID 86) in 29 ms on Tawfiq-PC (executor 0) (39/48)
251: 18/02/05 13:03:52 INFO TaskSetManager: Starting task 40.0 in stage 1.0 (TID 88, Tawfiq-PC, executor 0, partition 40, NODE_LOCAL, 7671 bytes)
252: 18/02/05 13:03:52 INFO TaskSetManager: Finished task 39.0 in stage 1.0 (TID 87) in 31 ms on Tawfiq-PC (executor 0) (40/48)
253: 18/02/05 13:03:52 INFO TaskSetManager: Starting task 41.0 in stage 1.0 (TID 89, Tawfiq-PC, executor 0, partition 41, NODE_LOCAL, 7671 bytes)
254: 18/02/05 13:03:52 INFO TaskSetManager: Finished task 40.0 in stage 1.0 (TID 88) in 32 ms on Tawfiq-PC (executor 0) (41/48)
255: 18/02/05 13:03:52 INFO TaskSetManager: Starting task 42.0 in stage 1.0 (TID 90, Tawfiq-PC, executor 0, partition 42, NODE_LOCAL, 7671 bytes)
256: 18/02/05 13:03:52 INFO TaskSetManager: Finished task 41.0 in stage 1.0 (TID 89) in 30 ms on Tawfiq-PC (executor 0) (42/48)
257: 18/02/05 13:03:52 INFO TaskSetManager: Starting task 43.0 in stage 1.0 (TID 91, Tawfiq-PC, executor 0, partition 43, NODE_LOCAL, 7671 bytes)
258: 18/02/05 13:03:52 INFO TaskSetManager: Finished task 42.0 in stage 1.0 (TID 90) in 32 ms on Tawfiq-PC (executor 0) (43/48)
259: 18/02/05 13:03:52 INFO TaskSetManager: Starting task 44.0 in stage 1.0 (TID 92, Tawfiq-PC, executor 0, partition 44, NODE_LOCAL, 7671 bytes)
260: 18/02/05 13:03:52 INFO TaskSetManager: Finished task 43.0 in stage 1.0 (TID 91) in 28 ms on Tawfiq-PC (executor 0) (44/48)
261: 18/02/05 13:03:52 INFO TaskSetManager: Starting task 45.0 in stage 1.0 (TID 93, Tawfiq-PC, executor 0, partition 45, NODE_LOCAL, 7671 bytes)
262: 18/02/05 13:03:52 INFO TaskSetManager: Finished task 44.0 in stage 1.0 (TID 92) in 103 ms on Tawfiq-PC (executor 0) (45/48)
263: 18/02/05 13:03:52 INFO TaskSetManager: Starting task 46.0 in stage 1.0 (TID 94, Tawfiq-PC, executor 0, partition 46, NODE_LOCAL, 7671 bytes)
264: 18/02/05 13:03:52 INFO TaskSetManager: Finished task 45.0 in stage 1.0 (TID 93) in 29 ms on Tawfiq-PC (executor 0) (46/48)
265: 18/02/05 13:03:52 INFO TaskSetManager: Starting task 47.0 in stage 1.0 (TID 95, Tawfiq-PC, executor 0, partition 47, NODE_LOCAL, 7671 bytes)
266: 18/02/05 13:03:52 INFO TaskSetManager: Finished task 46.0 in stage 1.0 (TID 94) in 48 ms on Tawfiq-PC (executor 0) (47/48)
267: 18/02/05 13:03:52 INFO TaskSetManager: Finished task 47.0 in stage 1.0 (TID 95) in 36 ms on Tawfiq-PC (executor 0) (48/48)
268: 18/02/05 13:03:52 INFO TaskSchedulerImpl: Removed TaskSet 1.0, whose tasks have all completed, from pool 
269: 18/02/05 13:03:52 INFO DAGScheduler: ResultStage 1 (runJob at SparkHadoopWriter.scala:78) finished in 2.238 s
270: 18/02/05 13:03:52 INFO DAGScheduler: Job 0 finished: runJob at SparkHadoopWriter.scala:78, took 40.759783 s
271: 18/02/05 13:03:52 INFO SparkHadoopWriter: Job job_20180205130312_0005 committed.
272: 18/02/05 13:03:52 INFO SparkContext: Invoking stop() from shutdown hook
273: 18/02/05 13:03:52 INFO SparkUI: Stopped Spark web UI at http://tawfiq-pc.mobility.unimelb.net.au:4040
274: 18/02/05 13:03:52 INFO MesosCoarseGrainedSchedulerBackend: Shutting down all executors
275: 18/02/05 13:03:52 INFO CoarseGrainedSchedulerBackend$DriverEndpoint: Asking each executor to shut down
276: 18/02/05 13:03:53 INFO MesosCoarseGrainedSchedulerBackend: Mesos task 0 is now TASK_FINISHED
277: I0205 13:03:53.198793 17497 sched.cpp:2021] Asked to stop the driver
278: I0205 13:03:53.199311 17133 sched.cpp:1203] Stopping framework c0393525-27a6-4604-bbbb-b86657dabc56-0000
279: 18/02/05 13:03:53 INFO MesosCoarseGrainedSchedulerBackend: driver.run() returned with code DRIVER_STOPPED
280: 18/02/05 13:03:53 INFO MapOutputTrackerMasterEndpoint: MapOutputTrackerMasterEndpoint stopped!
281: 18/02/05 13:03:53 INFO MemoryStore: MemoryStore cleared
282: 18/02/05 13:03:53 INFO BlockManager: BlockManager stopped
283: 18/02/05 13:03:53 INFO BlockManagerMaster: BlockManagerMaster stopped
284: 18/02/05 13:03:53 INFO OutputCommitCoordinator$OutputCommitCoordinatorEndpoint: OutputCommitCoordinator stopped!
285: 18/02/05 13:03:53 INFO SparkContext: Successfully stopped SparkContext
286: 18/02/05 13:03:53 INFO ShutdownHookManager: Shutdown hook called
287: 18/02/05 13:03:53 INFO ShutdownHookManager: Deleting directory /tmp/spark-cfc505be-16da-40e2-8bec-ad6260ae0e68
288: 18/02/05 13:03:53 INFO ShutdownHookManager: Deleting directory /tmp/spark-6240bea8-8724-4157-965d-72193310f09a
