0: 18/02/05 13:07:08 WARN Utils: Your hostname, Tawfiq-PC resolves to a loopback address: 127.0.1.1; using 10.100.228.108 instead (on interface enp0s31f6)
1: 18/02/05 13:07:08 WARN Utils: Set SPARK_LOCAL_IP if you need to bind to another address
2: 18/02/05 13:07:08 WARN NativeCodeLoader: Unable to load native-hadoop library for your platform... using builtin-java classes where applicable
3: Using Spark's default log4j profile: org/apache/spark/log4j-defaults.properties
4: 18/02/05 13:07:09 INFO SparkContext: Running Spark version 2.3.0-SNAPSHOT
5: 18/02/05 13:07:09 INFO SparkContext: Submitted application: BigDataBench WordCount
6: 18/02/05 13:07:10 INFO SecurityManager: Changing view acls to: tawfiq
7: 18/02/05 13:07:10 INFO SecurityManager: Changing modify acls to: tawfiq
8: 18/02/05 13:07:10 INFO SecurityManager: Changing view acls groups to: 
9: 18/02/05 13:07:10 INFO SecurityManager: Changing modify acls groups to: 
10: 18/02/05 13:07:10 INFO SecurityManager: SecurityManager: authentication disabled; ui acls disabled; users  with view permissions: Set(tawfiq); groups with view permissions: Set(); users  with modify permissions: Set(tawfiq); groups with modify permissions: Set()
11: 18/02/05 13:07:10 INFO Utils: Successfully started service 'sparkDriver' on port 35223.
12: 18/02/05 13:07:10 INFO SparkEnv: Registering MapOutputTracker
13: 18/02/05 13:07:11 INFO SparkEnv: Registering BlockManagerMaster
14: 18/02/05 13:07:11 INFO BlockManagerMasterEndpoint: Using org.apache.spark.storage.DefaultTopologyMapper for getting topology information
15: 18/02/05 13:07:11 INFO BlockManagerMasterEndpoint: BlockManagerMasterEndpoint up
16: 18/02/05 13:07:11 INFO DiskBlockManager: Created local directory at /tmp/blockmgr-7981d7ba-ad47-4c90-b47e-096f2199b963
17: 18/02/05 13:07:11 INFO MemoryStore: MemoryStore started with capacity 366.3 MB
18: 18/02/05 13:07:11 INFO SparkEnv: Registering OutputCommitCoordinator
19: 18/02/05 13:07:12 WARN Utils: Service 'SparkUI' could not bind on port 4040. Attempting port 4041.
20: 18/02/05 13:07:12 WARN Utils: Service 'SparkUI' could not bind on port 4041. Attempting port 4042.
21: 18/02/05 13:07:12 WARN Utils: Service 'SparkUI' could not bind on port 4042. Attempting port 4043.
22: 18/02/05 13:07:12 INFO Utils: Successfully started service 'SparkUI' on port 4043.
23: 18/02/05 13:07:12 INFO SparkUI: Bound SparkUI to 0.0.0.0, and started at http://tawfiq-pc.mobility.unimelb.net.au:4043
24: 18/02/05 13:07:12 INFO SparkContext: Added JAR file:/home/tawfiq/research/spark/bigdatabench-spark_1.3.0-hadoop_1.0.4.jar at spark://tawfiq-pc.mobility.unimelb.net.au:35223/jars/bigdatabench-spark_1.3.0-hadoop_1.0.4.jar with timestamp 1517796432751
25: I0205 13:07:14.391659 20138 sched.cpp:232] Version: 1.4.0
26: I0205 13:07:14.398622 20136 sched.cpp:336] New master detected at master@127.0.0.1:5050
27: I0205 13:07:14.402477 20136 sched.cpp:352] No credentials provided. Attempting to register without authentication
28: I0205 13:07:14.446359 20136 sched.cpp:759] Framework registered with c0393525-27a6-4604-bbbb-b86657dabc56-0008
29: 18/02/05 13:07:14 INFO Utils: Successfully started service 'org.apache.spark.network.netty.NettyBlockTransferService' on port 38229.
30: 18/02/05 13:07:14 INFO NettyBlockTransferService: Server created on tawfiq-pc.mobility.unimelb.net.au:38229
31: 18/02/05 13:07:14 INFO BlockManager: Using org.apache.spark.storage.RandomBlockReplicationPolicy for block replication policy
32: 18/02/05 13:07:14 INFO BlockManagerMaster: Registering BlockManager BlockManagerId(driver, tawfiq-pc.mobility.unimelb.net.au, 38229, None)
33: 18/02/05 13:07:14 INFO BlockManagerMasterEndpoint: Registering block manager tawfiq-pc.mobility.unimelb.net.au:38229 with 366.3 MB RAM, BlockManagerId(driver, tawfiq-pc.mobility.unimelb.net.au, 38229, None)
34: 18/02/05 13:07:14 INFO BlockManagerMaster: Registered BlockManager BlockManagerId(driver, tawfiq-pc.mobility.unimelb.net.au, 38229, None)
35: 18/02/05 13:07:14 INFO BlockManager: Initialized BlockManager: BlockManagerId(driver, tawfiq-pc.mobility.unimelb.net.au, 38229, None)
36: 18/02/05 13:07:16 INFO MesosCoarseGrainedSchedulerBackend: Mesos task 0 is now TASK_RUNNING
37: 18/02/05 13:07:17 INFO EventLoggingListener: Logging events to file:/home/tawfiq/research/spark/logs/c0393525-27a6-4604-bbbb-b86657dabc56-0008
38: 18/02/05 13:07:17 INFO MesosCoarseGrainedSchedulerBackend: SchedulerBackend is ready for scheduling beginning after reached minRegisteredResourcesRatio: 0.0
39: 18/02/05 13:07:19 INFO MemoryStore: Block broadcast_0 stored as values in memory (estimated size 214.5 KB, free 366.1 MB)
40: 18/02/05 13:07:19 INFO MemoryStore: Block broadcast_0_piece0 stored as bytes in memory (estimated size 20.4 KB, free 366.1 MB)
41: 18/02/05 13:07:19 INFO BlockManagerInfo: Added broadcast_0_piece0 in memory on tawfiq-pc.mobility.unimelb.net.au:38229 (size: 20.4 KB, free: 366.3 MB)
42: 18/02/05 13:07:19 INFO SparkContext: Created broadcast 0 from textFile at WordCount.scala:26
43: 18/02/05 13:07:19 INFO FileInputFormat: Total input paths to process : 3
44: 18/02/05 13:07:20 INFO deprecation: mapred.output.dir is deprecated. Instead, use mapreduce.output.fileoutputformat.outputdir
45: 18/02/05 13:07:20 INFO SparkContext: Starting job: runJob at SparkHadoopWriter.scala:78
46: 18/02/05 13:07:21 INFO DAGScheduler: Registering RDD 3 (map at WordCount.scala:28)
47: 18/02/05 13:07:21 INFO DAGScheduler: Got job 0 (runJob at SparkHadoopWriter.scala:78) with 48 output partitions
48: 18/02/05 13:07:21 INFO DAGScheduler: Final stage: ResultStage 1 (runJob at SparkHadoopWriter.scala:78)
49: 18/02/05 13:07:21 INFO DAGScheduler: Parents of final stage: List(ShuffleMapStage 0)
50: 18/02/05 13:07:21 INFO DAGScheduler: Missing parents: List(ShuffleMapStage 0)
51: 18/02/05 13:07:21 INFO DAGScheduler: Submitting ShuffleMapStage 0 (MapPartitionsRDD[3] at map at WordCount.scala:28), which has no missing parents
52: 18/02/05 13:07:21 INFO MemoryStore: Block broadcast_1 stored as values in memory (estimated size 4.8 KB, free 366.1 MB)
53: 18/02/05 13:07:21 INFO MemoryStore: Block broadcast_1_piece0 stored as bytes in memory (estimated size 2.8 KB, free 366.1 MB)
54: 18/02/05 13:07:21 INFO BlockManagerInfo: Added broadcast_1_piece0 in memory on tawfiq-pc.mobility.unimelb.net.au:38229 (size: 2.8 KB, free: 366.3 MB)
55: 18/02/05 13:07:21 INFO SparkContext: Created broadcast 1 from broadcast at DAGScheduler.scala:1029
56: 18/02/05 13:07:21 INFO DAGScheduler: Submitting 48 missing tasks from ShuffleMapStage 0 (MapPartitionsRDD[3] at map at WordCount.scala:28) (first 15 tasks are for partitions Vector(0, 1, 2, 3, 4, 5, 6, 7, 8, 9, 10, 11, 12, 13, 14))
57: 18/02/05 13:07:21 INFO TaskSchedulerImpl: Adding task set 0.0 with 48 tasks
58: 18/02/05 13:07:22 INFO CoarseGrainedSchedulerBackend$DriverEndpoint: Registered executor NettyRpcEndpointRef(spark-client://Executor) (10.100.228.108:57556) with ID 0
59: 18/02/05 13:07:22 INFO TaskSetManager: Starting task 0.0 in stage 0.0 (TID 0, Tawfiq-PC, executor 0, partition 0, PROCESS_LOCAL, 7911 bytes)
60: 18/02/05 13:07:22 INFO BlockManagerMasterEndpoint: Registering block manager Tawfiq-PC:42325 with 912.3 MB RAM, BlockManagerId(0, Tawfiq-PC, 42325, None)
61: 18/02/05 13:07:23 INFO BlockManagerInfo: Added broadcast_1_piece0 in memory on Tawfiq-PC:42325 (size: 2.8 KB, free: 912.3 MB)
62: 18/02/05 13:07:24 INFO BlockManagerInfo: Added broadcast_0_piece0 in memory on Tawfiq-PC:42325 (size: 20.4 KB, free: 912.3 MB)
63: 18/02/05 13:07:27 INFO TaskSetManager: Starting task 1.0 in stage 0.0 (TID 1, Tawfiq-PC, executor 0, partition 1, PROCESS_LOCAL, 7911 bytes)
64: 18/02/05 13:07:27 INFO TaskSetManager: Finished task 0.0 in stage 0.0 (TID 0) in 5598 ms on Tawfiq-PC (executor 0) (1/48)
65: 18/02/05 13:07:29 INFO TaskSetManager: Starting task 2.0 in stage 0.0 (TID 2, Tawfiq-PC, executor 0, partition 2, PROCESS_LOCAL, 7911 bytes)
66: 18/02/05 13:07:29 INFO TaskSetManager: Finished task 1.0 in stage 0.0 (TID 1) in 1939 ms on Tawfiq-PC (executor 0) (2/48)
67: 18/02/05 13:07:31 INFO TaskSetManager: Starting task 3.0 in stage 0.0 (TID 3, Tawfiq-PC, executor 0, partition 3, PROCESS_LOCAL, 7911 bytes)
68: 18/02/05 13:07:31 INFO TaskSetManager: Finished task 2.0 in stage 0.0 (TID 2) in 1809 ms on Tawfiq-PC (executor 0) (3/48)
69: 18/02/05 13:07:33 INFO TaskSetManager: Starting task 4.0 in stage 0.0 (TID 4, Tawfiq-PC, executor 0, partition 4, PROCESS_LOCAL, 7911 bytes)
70: 18/02/05 13:07:33 INFO TaskSetManager: Finished task 3.0 in stage 0.0 (TID 3) in 1795 ms on Tawfiq-PC (executor 0) (4/48)
71: 18/02/05 13:07:35 INFO TaskSetManager: Starting task 5.0 in stage 0.0 (TID 5, Tawfiq-PC, executor 0, partition 5, PROCESS_LOCAL, 7911 bytes)
72: 18/02/05 13:07:35 INFO TaskSetManager: Finished task 4.0 in stage 0.0 (TID 4) in 1723 ms on Tawfiq-PC (executor 0) (5/48)
73: 18/02/05 13:07:36 INFO TaskSetManager: Starting task 6.0 in stage 0.0 (TID 6, Tawfiq-PC, executor 0, partition 6, PROCESS_LOCAL, 7911 bytes)
74: 18/02/05 13:07:36 INFO TaskSetManager: Finished task 5.0 in stage 0.0 (TID 5) in 1798 ms on Tawfiq-PC (executor 0) (6/48)
75: 18/02/05 13:07:38 INFO TaskSetManager: Starting task 7.0 in stage 0.0 (TID 7, Tawfiq-PC, executor 0, partition 7, PROCESS_LOCAL, 7911 bytes)
76: 18/02/05 13:07:38 INFO TaskSetManager: Finished task 6.0 in stage 0.0 (TID 6) in 1582 ms on Tawfiq-PC (executor 0) (7/48)
77: 18/02/05 13:07:40 INFO TaskSetManager: Starting task 8.0 in stage 0.0 (TID 8, Tawfiq-PC, executor 0, partition 8, PROCESS_LOCAL, 7911 bytes)
78: 18/02/05 13:07:40 INFO TaskSetManager: Finished task 7.0 in stage 0.0 (TID 7) in 1586 ms on Tawfiq-PC (executor 0) (8/48)
79: 18/02/05 13:07:41 INFO TaskSetManager: Starting task 9.0 in stage 0.0 (TID 9, Tawfiq-PC, executor 0, partition 9, PROCESS_LOCAL, 7911 bytes)
80: 18/02/05 13:07:41 INFO TaskSetManager: Finished task 8.0 in stage 0.0 (TID 8) in 1628 ms on Tawfiq-PC (executor 0) (9/48)
81: 18/02/05 13:07:43 INFO TaskSetManager: Starting task 10.0 in stage 0.0 (TID 10, Tawfiq-PC, executor 0, partition 10, PROCESS_LOCAL, 7911 bytes)
82: 18/02/05 13:07:43 INFO TaskSetManager: Finished task 9.0 in stage 0.0 (TID 9) in 1572 ms on Tawfiq-PC (executor 0) (10/48)
83: 18/02/05 13:07:44 INFO TaskSetManager: Starting task 11.0 in stage 0.0 (TID 11, Tawfiq-PC, executor 0, partition 11, PROCESS_LOCAL, 7911 bytes)
84: 18/02/05 13:07:44 INFO TaskSetManager: Finished task 10.0 in stage 0.0 (TID 10) in 1688 ms on Tawfiq-PC (executor 0) (11/48)
85: 18/02/05 13:07:46 INFO TaskSetManager: Starting task 12.0 in stage 0.0 (TID 12, Tawfiq-PC, executor 0, partition 12, PROCESS_LOCAL, 7911 bytes)
86: 18/02/05 13:07:46 INFO TaskSetManager: Finished task 11.0 in stage 0.0 (TID 11) in 1528 ms on Tawfiq-PC (executor 0) (12/48)
87: 18/02/05 13:07:48 INFO TaskSetManager: Starting task 13.0 in stage 0.0 (TID 13, Tawfiq-PC, executor 0, partition 13, PROCESS_LOCAL, 7911 bytes)
88: 18/02/05 13:07:48 INFO TaskSetManager: Finished task 12.0 in stage 0.0 (TID 12) in 1581 ms on Tawfiq-PC (executor 0) (13/48)
89: 18/02/05 13:07:49 INFO TaskSetManager: Starting task 14.0 in stage 0.0 (TID 14, Tawfiq-PC, executor 0, partition 14, PROCESS_LOCAL, 7911 bytes)
90: 18/02/05 13:07:49 INFO TaskSetManager: Finished task 13.0 in stage 0.0 (TID 13) in 1570 ms on Tawfiq-PC (executor 0) (14/48)
91: 18/02/05 13:07:50 INFO TaskSetManager: Starting task 15.0 in stage 0.0 (TID 15, Tawfiq-PC, executor 0, partition 15, PROCESS_LOCAL, 7911 bytes)
92: 18/02/05 13:07:50 INFO TaskSetManager: Finished task 14.0 in stage 0.0 (TID 14) in 1423 ms on Tawfiq-PC (executor 0) (15/48)
93: 18/02/05 13:07:52 INFO TaskSetManager: Starting task 16.0 in stage 0.0 (TID 16, Tawfiq-PC, executor 0, partition 16, PROCESS_LOCAL, 7907 bytes)
94: 18/02/05 13:07:52 INFO TaskSetManager: Finished task 15.0 in stage 0.0 (TID 15) in 1267 ms on Tawfiq-PC (executor 0) (16/48)
95: 18/02/05 13:07:53 INFO TaskSetManager: Starting task 17.0 in stage 0.0 (TID 17, Tawfiq-PC, executor 0, partition 17, PROCESS_LOCAL, 7907 bytes)
96: 18/02/05 13:07:53 INFO TaskSetManager: Finished task 16.0 in stage 0.0 (TID 16) in 1627 ms on Tawfiq-PC (executor 0) (17/48)
97: 18/02/05 13:07:55 INFO TaskSetManager: Starting task 18.0 in stage 0.0 (TID 18, Tawfiq-PC, executor 0, partition 18, PROCESS_LOCAL, 7907 bytes)
98: 18/02/05 13:07:55 INFO TaskSetManager: Finished task 17.0 in stage 0.0 (TID 17) in 1528 ms on Tawfiq-PC (executor 0) (18/48)
99: 18/02/05 13:07:57 INFO TaskSetManager: Starting task 19.0 in stage 0.0 (TID 19, Tawfiq-PC, executor 0, partition 19, PROCESS_LOCAL, 7907 bytes)
100: 18/02/05 13:07:57 INFO TaskSetManager: Finished task 18.0 in stage 0.0 (TID 18) in 1590 ms on Tawfiq-PC (executor 0) (19/48)
101: 18/02/05 13:07:58 INFO TaskSetManager: Starting task 20.0 in stage 0.0 (TID 20, Tawfiq-PC, executor 0, partition 20, PROCESS_LOCAL, 7907 bytes)
102: 18/02/05 13:07:58 INFO TaskSetManager: Finished task 19.0 in stage 0.0 (TID 19) in 1506 ms on Tawfiq-PC (executor 0) (20/48)
103: 18/02/05 13:08:00 INFO TaskSetManager: Starting task 21.0 in stage 0.0 (TID 21, Tawfiq-PC, executor 0, partition 21, PROCESS_LOCAL, 7907 bytes)
104: 18/02/05 13:08:00 INFO TaskSetManager: Finished task 20.0 in stage 0.0 (TID 20) in 1515 ms on Tawfiq-PC (executor 0) (21/48)
105: 18/02/05 13:08:01 INFO TaskSetManager: Starting task 22.0 in stage 0.0 (TID 22, Tawfiq-PC, executor 0, partition 22, PROCESS_LOCAL, 7907 bytes)
106: 18/02/05 13:08:01 INFO TaskSetManager: Finished task 21.0 in stage 0.0 (TID 21) in 1582 ms on Tawfiq-PC (executor 0) (22/48)
107: 18/02/05 13:08:03 INFO TaskSetManager: Starting task 23.0 in stage 0.0 (TID 23, Tawfiq-PC, executor 0, partition 23, PROCESS_LOCAL, 7907 bytes)
108: 18/02/05 13:08:03 INFO TaskSetManager: Finished task 22.0 in stage 0.0 (TID 22) in 1859 ms on Tawfiq-PC (executor 0) (23/48)
109: 18/02/05 13:08:05 INFO TaskSetManager: Starting task 24.0 in stage 0.0 (TID 24, Tawfiq-PC, executor 0, partition 24, PROCESS_LOCAL, 7907 bytes)
110: 18/02/05 13:08:05 INFO TaskSetManager: Finished task 23.0 in stage 0.0 (TID 23) in 1589 ms on Tawfiq-PC (executor 0) (24/48)
111: 18/02/05 13:08:06 INFO TaskSetManager: Starting task 25.0 in stage 0.0 (TID 25, Tawfiq-PC, executor 0, partition 25, PROCESS_LOCAL, 7907 bytes)
112: 18/02/05 13:08:06 INFO TaskSetManager: Finished task 24.0 in stage 0.0 (TID 24) in 1505 ms on Tawfiq-PC (executor 0) (25/48)
113: 18/02/05 13:08:08 INFO TaskSetManager: Starting task 26.0 in stage 0.0 (TID 26, Tawfiq-PC, executor 0, partition 26, PROCESS_LOCAL, 7907 bytes)
114: 18/02/05 13:08:08 INFO TaskSetManager: Finished task 25.0 in stage 0.0 (TID 25) in 1699 ms on Tawfiq-PC (executor 0) (26/48)
115: 18/02/05 13:08:09 INFO TaskSetManager: Starting task 27.0 in stage 0.0 (TID 27, Tawfiq-PC, executor 0, partition 27, PROCESS_LOCAL, 7907 bytes)
116: 18/02/05 13:08:09 INFO TaskSetManager: Finished task 26.0 in stage 0.0 (TID 26) in 1490 ms on Tawfiq-PC (executor 0) (27/48)
117: 18/02/05 13:08:11 INFO TaskSetManager: Starting task 28.0 in stage 0.0 (TID 28, Tawfiq-PC, executor 0, partition 28, PROCESS_LOCAL, 7907 bytes)
118: 18/02/05 13:08:11 INFO TaskSetManager: Finished task 27.0 in stage 0.0 (TID 27) in 1571 ms on Tawfiq-PC (executor 0) (28/48)
119: 18/02/05 13:08:13 INFO TaskSetManager: Starting task 29.0 in stage 0.0 (TID 29, Tawfiq-PC, executor 0, partition 29, PROCESS_LOCAL, 7907 bytes)
120: 18/02/05 13:08:13 INFO TaskSetManager: Finished task 28.0 in stage 0.0 (TID 28) in 1792 ms on Tawfiq-PC (executor 0) (29/48)
121: 18/02/05 13:08:15 INFO TaskSetManager: Starting task 30.0 in stage 0.0 (TID 30, Tawfiq-PC, executor 0, partition 30, PROCESS_LOCAL, 7907 bytes)
122: 18/02/05 13:08:15 INFO TaskSetManager: Finished task 29.0 in stage 0.0 (TID 29) in 1916 ms on Tawfiq-PC (executor 0) (30/48)
123: 18/02/05 13:08:16 INFO TaskSetManager: Starting task 31.0 in stage 0.0 (TID 31, Tawfiq-PC, executor 0, partition 31, PROCESS_LOCAL, 7907 bytes)
124: 18/02/05 13:08:16 INFO TaskSetManager: Finished task 30.0 in stage 0.0 (TID 30) in 1555 ms on Tawfiq-PC (executor 0) (31/48)
125: 18/02/05 13:08:17 INFO TaskSetManager: Starting task 32.0 in stage 0.0 (TID 32, Tawfiq-PC, executor 0, partition 32, PROCESS_LOCAL, 7900 bytes)
126: 18/02/05 13:08:17 INFO TaskSetManager: Finished task 31.0 in stage 0.0 (TID 31) in 1191 ms on Tawfiq-PC (executor 0) (32/48)
127: 18/02/05 13:08:19 INFO TaskSetManager: Starting task 33.0 in stage 0.0 (TID 33, Tawfiq-PC, executor 0, partition 33, PROCESS_LOCAL, 7900 bytes)
128: 18/02/05 13:08:19 INFO TaskSetManager: Finished task 32.0 in stage 0.0 (TID 32) in 1534 ms on Tawfiq-PC (executor 0) (33/48)
129: 18/02/05 13:08:20 INFO TaskSetManager: Starting task 34.0 in stage 0.0 (TID 34, Tawfiq-PC, executor 0, partition 34, PROCESS_LOCAL, 7900 bytes)
130: 18/02/05 13:08:20 INFO TaskSetManager: Finished task 33.0 in stage 0.0 (TID 33) in 1530 ms on Tawfiq-PC (executor 0) (34/48)
131: 18/02/05 13:08:22 INFO TaskSetManager: Starting task 35.0 in stage 0.0 (TID 35, Tawfiq-PC, executor 0, partition 35, PROCESS_LOCAL, 7900 bytes)
132: 18/02/05 13:08:22 INFO TaskSetManager: Finished task 34.0 in stage 0.0 (TID 34) in 1905 ms on Tawfiq-PC (executor 0) (35/48)
133: 18/02/05 13:08:24 INFO TaskSetManager: Starting task 36.0 in stage 0.0 (TID 36, Tawfiq-PC, executor 0, partition 36, PROCESS_LOCAL, 7900 bytes)
134: 18/02/05 13:08:24 INFO TaskSetManager: Finished task 35.0 in stage 0.0 (TID 35) in 1630 ms on Tawfiq-PC (executor 0) (36/48)
135: 18/02/05 13:08:25 INFO TaskSetManager: Starting task 37.0 in stage 0.0 (TID 37, Tawfiq-PC, executor 0, partition 37, PROCESS_LOCAL, 7900 bytes)
136: 18/02/05 13:08:25 INFO TaskSetManager: Finished task 36.0 in stage 0.0 (TID 36) in 1509 ms on Tawfiq-PC (executor 0) (37/48)
137: 18/02/05 13:08:27 INFO TaskSetManager: Starting task 38.0 in stage 0.0 (TID 38, Tawfiq-PC, executor 0, partition 38, PROCESS_LOCAL, 7900 bytes)
138: 18/02/05 13:08:27 INFO TaskSetManager: Finished task 37.0 in stage 0.0 (TID 37) in 1521 ms on Tawfiq-PC (executor 0) (38/48)
139: 18/02/05 13:08:28 INFO TaskSetManager: Starting task 39.0 in stage 0.0 (TID 39, Tawfiq-PC, executor 0, partition 39, PROCESS_LOCAL, 7900 bytes)
140: 18/02/05 13:08:28 INFO TaskSetManager: Finished task 38.0 in stage 0.0 (TID 38) in 1583 ms on Tawfiq-PC (executor 0) (39/48)
141: 18/02/05 13:08:30 INFO TaskSetManager: Starting task 40.0 in stage 0.0 (TID 40, Tawfiq-PC, executor 0, partition 40, PROCESS_LOCAL, 7900 bytes)
142: 18/02/05 13:08:30 INFO TaskSetManager: Finished task 39.0 in stage 0.0 (TID 39) in 1652 ms on Tawfiq-PC (executor 0) (40/48)
143: 18/02/05 13:08:32 INFO TaskSetManager: Starting task 41.0 in stage 0.0 (TID 41, Tawfiq-PC, executor 0, partition 41, PROCESS_LOCAL, 7900 bytes)
144: 18/02/05 13:08:32 INFO TaskSetManager: Finished task 40.0 in stage 0.0 (TID 40) in 1585 ms on Tawfiq-PC (executor 0) (41/48)
145: 18/02/05 13:08:33 INFO TaskSetManager: Starting task 42.0 in stage 0.0 (TID 42, Tawfiq-PC, executor 0, partition 42, PROCESS_LOCAL, 7900 bytes)
146: 18/02/05 13:08:33 INFO TaskSetManager: Finished task 41.0 in stage 0.0 (TID 41) in 1645 ms on Tawfiq-PC (executor 0) (42/48)
147: 18/02/05 13:08:35 INFO TaskSetManager: Starting task 43.0 in stage 0.0 (TID 43, Tawfiq-PC, executor 0, partition 43, PROCESS_LOCAL, 7900 bytes)
148: 18/02/05 13:08:35 INFO TaskSetManager: Finished task 42.0 in stage 0.0 (TID 42) in 1614 ms on Tawfiq-PC (executor 0) (43/48)
149: 18/02/05 13:08:37 INFO TaskSetManager: Starting task 44.0 in stage 0.0 (TID 44, Tawfiq-PC, executor 0, partition 44, PROCESS_LOCAL, 7900 bytes)
150: 18/02/05 13:08:37 INFO TaskSetManager: Finished task 43.0 in stage 0.0 (TID 43) in 1580 ms on Tawfiq-PC (executor 0) (44/48)
151: 18/02/05 13:08:38 INFO TaskSetManager: Starting task 45.0 in stage 0.0 (TID 45, Tawfiq-PC, executor 0, partition 45, PROCESS_LOCAL, 7900 bytes)
152: 18/02/05 13:08:38 INFO TaskSetManager: Finished task 44.0 in stage 0.0 (TID 44) in 1608 ms on Tawfiq-PC (executor 0) (45/48)
153: 18/02/05 13:08:39 INFO TaskSetManager: Starting task 46.0 in stage 0.0 (TID 46, Tawfiq-PC, executor 0, partition 46, PROCESS_LOCAL, 7900 bytes)
154: 18/02/05 13:08:39 INFO TaskSetManager: Finished task 45.0 in stage 0.0 (TID 45) in 1305 ms on Tawfiq-PC (executor 0) (46/48)
155: 18/02/05 13:08:41 INFO TaskSetManager: Starting task 47.0 in stage 0.0 (TID 47, Tawfiq-PC, executor 0, partition 47, PROCESS_LOCAL, 7900 bytes)
156: 18/02/05 13:08:41 INFO TaskSetManager: Finished task 46.0 in stage 0.0 (TID 46) in 1396 ms on Tawfiq-PC (executor 0) (47/48)
157: 18/02/05 13:08:42 INFO TaskSetManager: Finished task 47.0 in stage 0.0 (TID 47) in 988 ms on Tawfiq-PC (executor 0) (48/48)
158: 18/02/05 13:08:42 INFO DAGScheduler: ShuffleMapStage 0 (map at WordCount.scala:28) finished in 80.839 s
159: 18/02/05 13:08:42 INFO DAGScheduler: looking for newly runnable stages
160: 18/02/05 13:08:42 INFO DAGScheduler: running: Set()
161: 18/02/05 13:08:42 INFO DAGScheduler: waiting: Set(ResultStage 1)
162: 18/02/05 13:08:42 INFO DAGScheduler: failed: Set()
163: 18/02/05 13:08:42 INFO TaskSchedulerImpl: Removed TaskSet 0.0, whose tasks have all completed, from pool 
164: 18/02/05 13:08:42 INFO DAGScheduler: Submitting ResultStage 1 (MapPartitionsRDD[5] at saveAsTextFile at WordCount.scala:31), which has no missing parents
165: 18/02/05 13:08:42 INFO MemoryStore: Block broadcast_2 stored as values in memory (estimated size 65.6 KB, free 366.0 MB)
166: 18/02/05 13:08:42 INFO MemoryStore: Block broadcast_2_piece0 stored as bytes in memory (estimated size 23.6 KB, free 366.0 MB)
167: 18/02/05 13:08:42 INFO BlockManagerInfo: Added broadcast_2_piece0 in memory on tawfiq-pc.mobility.unimelb.net.au:38229 (size: 23.6 KB, free: 366.3 MB)
168: 18/02/05 13:08:42 INFO SparkContext: Created broadcast 2 from broadcast at DAGScheduler.scala:1029
169: 18/02/05 13:08:42 INFO DAGScheduler: Submitting 48 missing tasks from ResultStage 1 (MapPartitionsRDD[5] at saveAsTextFile at WordCount.scala:31) (first 15 tasks are for partitions Vector(0, 1, 2, 3, 4, 5, 6, 7, 8, 9, 10, 11, 12, 13, 14))
170: 18/02/05 13:08:42 INFO TaskSchedulerImpl: Adding task set 1.0 with 48 tasks
171: 18/02/05 13:08:42 INFO TaskSetManager: Starting task 0.0 in stage 1.0 (TID 48, Tawfiq-PC, executor 0, partition 0, NODE_LOCAL, 7671 bytes)
172: 18/02/05 13:08:42 INFO BlockManagerInfo: Added broadcast_2_piece0 in memory on Tawfiq-PC:42325 (size: 23.6 KB, free: 912.3 MB)
173: 18/02/05 13:08:42 INFO MapOutputTrackerMasterEndpoint: Asked to send map output locations for shuffle 0 to 10.100.228.108:57556
174: 18/02/05 13:08:43 INFO TaskSetManager: Starting task 1.0 in stage 1.0 (TID 49, Tawfiq-PC, executor 0, partition 1, NODE_LOCAL, 7671 bytes)
175: 18/02/05 13:08:43 INFO TaskSetManager: Finished task 0.0 in stage 1.0 (TID 48) in 596 ms on Tawfiq-PC (executor 0) (1/48)
176: 18/02/05 13:08:43 INFO TaskSetManager: Starting task 2.0 in stage 1.0 (TID 50, Tawfiq-PC, executor 0, partition 2, NODE_LOCAL, 7671 bytes)
177: 18/02/05 13:08:43 INFO TaskSetManager: Finished task 1.0 in stage 1.0 (TID 49) in 404 ms on Tawfiq-PC (executor 0) (2/48)
178: 18/02/05 13:08:43 INFO TaskSetManager: Starting task 3.0 in stage 1.0 (TID 51, Tawfiq-PC, executor 0, partition 3, NODE_LOCAL, 7671 bytes)
179: 18/02/05 13:08:43 INFO TaskSetManager: Finished task 2.0 in stage 1.0 (TID 50) in 232 ms on Tawfiq-PC (executor 0) (3/48)
180: 18/02/05 13:08:43 INFO TaskSetManager: Starting task 4.0 in stage 1.0 (TID 52, Tawfiq-PC, executor 0, partition 4, NODE_LOCAL, 7671 bytes)
181: 18/02/05 13:08:43 INFO TaskSetManager: Finished task 3.0 in stage 1.0 (TID 51) in 251 ms on Tawfiq-PC (executor 0) (4/48)
182: 18/02/05 13:08:44 INFO TaskSetManager: Starting task 5.0 in stage 1.0 (TID 53, Tawfiq-PC, executor 0, partition 5, NODE_LOCAL, 7671 bytes)
183: 18/02/05 13:08:44 INFO TaskSetManager: Finished task 4.0 in stage 1.0 (TID 52) in 195 ms on Tawfiq-PC (executor 0) (5/48)
184: 18/02/05 13:08:44 INFO TaskSetManager: Starting task 6.0 in stage 1.0 (TID 54, Tawfiq-PC, executor 0, partition 6, NODE_LOCAL, 7671 bytes)
185: 18/02/05 13:08:44 INFO TaskSetManager: Finished task 5.0 in stage 1.0 (TID 53) in 257 ms on Tawfiq-PC (executor 0) (6/48)
186: 18/02/05 13:08:44 INFO TaskSetManager: Starting task 7.0 in stage 1.0 (TID 55, Tawfiq-PC, executor 0, partition 7, NODE_LOCAL, 7671 bytes)
187: 18/02/05 13:08:44 INFO TaskSetManager: Finished task 6.0 in stage 1.0 (TID 54) in 137 ms on Tawfiq-PC (executor 0) (7/48)
188: 18/02/05 13:08:44 INFO TaskSetManager: Starting task 8.0 in stage 1.0 (TID 56, Tawfiq-PC, executor 0, partition 8, NODE_LOCAL, 7671 bytes)
189: 18/02/05 13:08:44 INFO TaskSetManager: Finished task 7.0 in stage 1.0 (TID 55) in 146 ms on Tawfiq-PC (executor 0) (8/48)
190: 18/02/05 13:08:44 INFO TaskSetManager: Starting task 9.0 in stage 1.0 (TID 57, Tawfiq-PC, executor 0, partition 9, NODE_LOCAL, 7671 bytes)
191: 18/02/05 13:08:44 INFO TaskSetManager: Finished task 8.0 in stage 1.0 (TID 56) in 140 ms on Tawfiq-PC (executor 0) (9/48)
192: 18/02/05 13:08:44 INFO TaskSetManager: Starting task 10.0 in stage 1.0 (TID 58, Tawfiq-PC, executor 0, partition 10, NODE_LOCAL, 7671 bytes)
193: 18/02/05 13:08:44 INFO TaskSetManager: Finished task 9.0 in stage 1.0 (TID 57) in 136 ms on Tawfiq-PC (executor 0) (10/48)
194: 18/02/05 13:08:45 INFO TaskSetManager: Starting task 11.0 in stage 1.0 (TID 59, Tawfiq-PC, executor 0, partition 11, NODE_LOCAL, 7671 bytes)
195: 18/02/05 13:08:45 INFO TaskSetManager: Finished task 10.0 in stage 1.0 (TID 58) in 162 ms on Tawfiq-PC (executor 0) (11/48)
196: 18/02/05 13:08:45 INFO TaskSetManager: Starting task 12.0 in stage 1.0 (TID 60, Tawfiq-PC, executor 0, partition 12, NODE_LOCAL, 7671 bytes)
197: 18/02/05 13:08:45 INFO TaskSetManager: Finished task 11.0 in stage 1.0 (TID 59) in 165 ms on Tawfiq-PC (executor 0) (12/48)
198: 18/02/05 13:08:45 INFO TaskSetManager: Starting task 13.0 in stage 1.0 (TID 61, Tawfiq-PC, executor 0, partition 13, NODE_LOCAL, 7671 bytes)
199: 18/02/05 13:08:45 INFO TaskSetManager: Finished task 12.0 in stage 1.0 (TID 60) in 151 ms on Tawfiq-PC (executor 0) (13/48)
200: 18/02/05 13:08:45 INFO TaskSetManager: Starting task 14.0 in stage 1.0 (TID 62, Tawfiq-PC, executor 0, partition 14, NODE_LOCAL, 7671 bytes)
201: 18/02/05 13:08:45 INFO TaskSetManager: Finished task 13.0 in stage 1.0 (TID 61) in 119 ms on Tawfiq-PC (executor 0) (14/48)
202: 18/02/05 13:08:45 INFO TaskSetManager: Starting task 15.0 in stage 1.0 (TID 63, Tawfiq-PC, executor 0, partition 15, NODE_LOCAL, 7671 bytes)
203: 18/02/05 13:08:45 INFO TaskSetManager: Finished task 14.0 in stage 1.0 (TID 62) in 213 ms on Tawfiq-PC (executor 0) (15/48)
204: 18/02/05 13:08:45 INFO TaskSetManager: Starting task 16.0 in stage 1.0 (TID 64, Tawfiq-PC, executor 0, partition 16, NODE_LOCAL, 7671 bytes)
205: 18/02/05 13:08:45 INFO TaskSetManager: Finished task 15.0 in stage 1.0 (TID 63) in 180 ms on Tawfiq-PC (executor 0) (16/48)
206: 18/02/05 13:08:46 INFO TaskSetManager: Starting task 17.0 in stage 1.0 (TID 65, Tawfiq-PC, executor 0, partition 17, NODE_LOCAL, 7671 bytes)
207: 18/02/05 13:08:46 INFO TaskSetManager: Finished task 16.0 in stage 1.0 (TID 64) in 79 ms on Tawfiq-PC (executor 0) (17/48)
208: 18/02/05 13:08:46 INFO TaskSetManager: Starting task 18.0 in stage 1.0 (TID 66, Tawfiq-PC, executor 0, partition 18, NODE_LOCAL, 7671 bytes)
209: 18/02/05 13:08:46 INFO TaskSetManager: Finished task 17.0 in stage 1.0 (TID 65) in 64 ms on Tawfiq-PC (executor 0) (18/48)
210: 18/02/05 13:08:46 INFO TaskSetManager: Starting task 19.0 in stage 1.0 (TID 67, Tawfiq-PC, executor 0, partition 19, NODE_LOCAL, 7671 bytes)
211: 18/02/05 13:08:46 INFO TaskSetManager: Finished task 18.0 in stage 1.0 (TID 66) in 107 ms on Tawfiq-PC (executor 0) (19/48)
212: 18/02/05 13:08:46 INFO TaskSetManager: Starting task 20.0 in stage 1.0 (TID 68, Tawfiq-PC, executor 0, partition 20, NODE_LOCAL, 7671 bytes)
213: 18/02/05 13:08:46 INFO TaskSetManager: Finished task 19.0 in stage 1.0 (TID 67) in 160 ms on Tawfiq-PC (executor 0) (20/48)
214: 18/02/05 13:08:46 INFO TaskSetManager: Starting task 21.0 in stage 1.0 (TID 69, Tawfiq-PC, executor 0, partition 21, NODE_LOCAL, 7671 bytes)
215: 18/02/05 13:08:46 INFO TaskSetManager: Finished task 20.0 in stage 1.0 (TID 68) in 128 ms on Tawfiq-PC (executor 0) (21/48)
216: 18/02/05 13:08:46 INFO TaskSetManager: Starting task 22.0 in stage 1.0 (TID 70, Tawfiq-PC, executor 0, partition 22, NODE_LOCAL, 7671 bytes)
217: 18/02/05 13:08:46 INFO TaskSetManager: Finished task 21.0 in stage 1.0 (TID 69) in 179 ms on Tawfiq-PC (executor 0) (22/48)
218: 18/02/05 13:08:46 INFO TaskSetManager: Starting task 23.0 in stage 1.0 (TID 71, Tawfiq-PC, executor 0, partition 23, NODE_LOCAL, 7671 bytes)
219: 18/02/05 13:08:46 INFO TaskSetManager: Finished task 22.0 in stage 1.0 (TID 70) in 79 ms on Tawfiq-PC (executor 0) (23/48)
220: 18/02/05 13:08:46 INFO TaskSetManager: Starting task 24.0 in stage 1.0 (TID 72, Tawfiq-PC, executor 0, partition 24, NODE_LOCAL, 7671 bytes)
221: 18/02/05 13:08:46 INFO TaskSetManager: Finished task 23.0 in stage 1.0 (TID 71) in 80 ms on Tawfiq-PC (executor 0) (24/48)
222: 18/02/05 13:08:46 INFO TaskSetManager: Starting task 25.0 in stage 1.0 (TID 73, Tawfiq-PC, executor 0, partition 25, NODE_LOCAL, 7671 bytes)
223: 18/02/05 13:08:46 INFO TaskSetManager: Finished task 24.0 in stage 1.0 (TID 72) in 118 ms on Tawfiq-PC (executor 0) (25/48)
224: 18/02/05 13:08:46 INFO TaskSetManager: Starting task 26.0 in stage 1.0 (TID 74, Tawfiq-PC, executor 0, partition 26, NODE_LOCAL, 7671 bytes)
225: 18/02/05 13:08:46 INFO TaskSetManager: Finished task 25.0 in stage 1.0 (TID 73) in 72 ms on Tawfiq-PC (executor 0) (26/48)
226: 18/02/05 13:08:47 INFO TaskSetManager: Starting task 27.0 in stage 1.0 (TID 75, Tawfiq-PC, executor 0, partition 27, NODE_LOCAL, 7671 bytes)
227: 18/02/05 13:08:47 INFO TaskSetManager: Finished task 26.0 in stage 1.0 (TID 74) in 102 ms on Tawfiq-PC (executor 0) (27/48)
228: 18/02/05 13:08:47 INFO TaskSetManager: Starting task 28.0 in stage 1.0 (TID 76, Tawfiq-PC, executor 0, partition 28, NODE_LOCAL, 7671 bytes)
229: 18/02/05 13:08:47 INFO TaskSetManager: Finished task 27.0 in stage 1.0 (TID 75) in 127 ms on Tawfiq-PC (executor 0) (28/48)
230: 18/02/05 13:08:47 INFO TaskSetManager: Starting task 29.0 in stage 1.0 (TID 77, Tawfiq-PC, executor 0, partition 29, NODE_LOCAL, 7671 bytes)
231: 18/02/05 13:08:47 INFO TaskSetManager: Finished task 28.0 in stage 1.0 (TID 76) in 102 ms on Tawfiq-PC (executor 0) (29/48)
232: 18/02/05 13:08:47 INFO TaskSetManager: Starting task 30.0 in stage 1.0 (TID 78, Tawfiq-PC, executor 0, partition 30, NODE_LOCAL, 7671 bytes)
233: 18/02/05 13:08:47 INFO TaskSetManager: Finished task 29.0 in stage 1.0 (TID 77) in 142 ms on Tawfiq-PC (executor 0) (30/48)
234: 18/02/05 13:08:47 INFO TaskSetManager: Starting task 31.0 in stage 1.0 (TID 79, Tawfiq-PC, executor 0, partition 31, NODE_LOCAL, 7671 bytes)
235: 18/02/05 13:08:47 INFO TaskSetManager: Finished task 30.0 in stage 1.0 (TID 78) in 96 ms on Tawfiq-PC (executor 0) (31/48)
236: 18/02/05 13:08:47 INFO TaskSetManager: Starting task 32.0 in stage 1.0 (TID 80, Tawfiq-PC, executor 0, partition 32, NODE_LOCAL, 7671 bytes)
237: 18/02/05 13:08:47 INFO TaskSetManager: Finished task 31.0 in stage 1.0 (TID 79) in 127 ms on Tawfiq-PC (executor 0) (32/48)
238: 18/02/05 13:08:47 INFO TaskSetManager: Starting task 33.0 in stage 1.0 (TID 81, Tawfiq-PC, executor 0, partition 33, NODE_LOCAL, 7671 bytes)
239: 18/02/05 13:08:47 INFO TaskSetManager: Finished task 32.0 in stage 1.0 (TID 80) in 79 ms on Tawfiq-PC (executor 0) (33/48)
240: 18/02/05 13:08:47 INFO TaskSetManager: Starting task 34.0 in stage 1.0 (TID 82, Tawfiq-PC, executor 0, partition 34, NODE_LOCAL, 7671 bytes)
241: 18/02/05 13:08:47 INFO TaskSetManager: Finished task 33.0 in stage 1.0 (TID 81) in 117 ms on Tawfiq-PC (executor 0) (34/48)
242: 18/02/05 13:08:47 INFO TaskSetManager: Starting task 35.0 in stage 1.0 (TID 83, Tawfiq-PC, executor 0, partition 35, NODE_LOCAL, 7671 bytes)
243: 18/02/05 13:08:47 INFO TaskSetManager: Finished task 34.0 in stage 1.0 (TID 82) in 81 ms on Tawfiq-PC (executor 0) (35/48)
244: 18/02/05 13:08:48 INFO TaskSetManager: Starting task 36.0 in stage 1.0 (TID 84, Tawfiq-PC, executor 0, partition 36, NODE_LOCAL, 7671 bytes)
245: 18/02/05 13:08:48 INFO TaskSetManager: Finished task 35.0 in stage 1.0 (TID 83) in 104 ms on Tawfiq-PC (executor 0) (36/48)
246: 18/02/05 13:08:48 INFO TaskSetManager: Starting task 37.0 in stage 1.0 (TID 85, Tawfiq-PC, executor 0, partition 37, NODE_LOCAL, 7671 bytes)
247: 18/02/05 13:08:48 INFO TaskSetManager: Finished task 36.0 in stage 1.0 (TID 84) in 144 ms on Tawfiq-PC (executor 0) (37/48)
248: 18/02/05 13:08:48 INFO TaskSetManager: Starting task 38.0 in stage 1.0 (TID 86, Tawfiq-PC, executor 0, partition 38, NODE_LOCAL, 7671 bytes)
249: 18/02/05 13:08:48 INFO TaskSetManager: Finished task 37.0 in stage 1.0 (TID 85) in 136 ms on Tawfiq-PC (executor 0) (38/48)
250: 18/02/05 13:08:48 INFO TaskSetManager: Starting task 39.0 in stage 1.0 (TID 87, Tawfiq-PC, executor 0, partition 39, NODE_LOCAL, 7671 bytes)
251: 18/02/05 13:08:48 INFO TaskSetManager: Finished task 38.0 in stage 1.0 (TID 86) in 173 ms on Tawfiq-PC (executor 0) (39/48)
252: 18/02/05 13:08:48 INFO TaskSetManager: Starting task 40.0 in stage 1.0 (TID 88, Tawfiq-PC, executor 0, partition 40, NODE_LOCAL, 7671 bytes)
253: 18/02/05 13:08:48 INFO TaskSetManager: Finished task 39.0 in stage 1.0 (TID 87) in 135 ms on Tawfiq-PC (executor 0) (40/48)
254: 18/02/05 13:08:48 INFO TaskSetManager: Starting task 41.0 in stage 1.0 (TID 89, Tawfiq-PC, executor 0, partition 41, NODE_LOCAL, 7671 bytes)
255: 18/02/05 13:08:48 INFO TaskSetManager: Finished task 40.0 in stage 1.0 (TID 88) in 194 ms on Tawfiq-PC (executor 0) (41/48)
256: 18/02/05 13:08:48 INFO TaskSetManager: Starting task 42.0 in stage 1.0 (TID 90, Tawfiq-PC, executor 0, partition 42, NODE_LOCAL, 7671 bytes)
257: 18/02/05 13:08:48 INFO TaskSetManager: Finished task 41.0 in stage 1.0 (TID 89) in 148 ms on Tawfiq-PC (executor 0) (42/48)
258: 18/02/05 13:08:49 INFO TaskSetManager: Starting task 43.0 in stage 1.0 (TID 91, Tawfiq-PC, executor 0, partition 43, NODE_LOCAL, 7671 bytes)
259: 18/02/05 13:08:49 INFO TaskSetManager: Finished task 42.0 in stage 1.0 (TID 90) in 142 ms on Tawfiq-PC (executor 0) (43/48)
260: 18/02/05 13:08:49 INFO TaskSetManager: Starting task 44.0 in stage 1.0 (TID 92, Tawfiq-PC, executor 0, partition 44, NODE_LOCAL, 7671 bytes)
261: 18/02/05 13:08:49 INFO TaskSetManager: Finished task 43.0 in stage 1.0 (TID 91) in 86 ms on Tawfiq-PC (executor 0) (44/48)
262: 18/02/05 13:08:49 INFO TaskSetManager: Starting task 45.0 in stage 1.0 (TID 93, Tawfiq-PC, executor 0, partition 45, NODE_LOCAL, 7671 bytes)
263: 18/02/05 13:08:49 INFO TaskSetManager: Finished task 44.0 in stage 1.0 (TID 92) in 90 ms on Tawfiq-PC (executor 0) (45/48)
264: 18/02/05 13:08:49 INFO TaskSetManager: Starting task 46.0 in stage 1.0 (TID 94, Tawfiq-PC, executor 0, partition 46, NODE_LOCAL, 7671 bytes)
265: 18/02/05 13:08:49 INFO TaskSetManager: Finished task 45.0 in stage 1.0 (TID 93) in 91 ms on Tawfiq-PC (executor 0) (46/48)
266: 18/02/05 13:08:49 INFO TaskSetManager: Starting task 47.0 in stage 1.0 (TID 95, Tawfiq-PC, executor 0, partition 47, NODE_LOCAL, 7671 bytes)
267: 18/02/05 13:08:49 INFO TaskSetManager: Finished task 46.0 in stage 1.0 (TID 94) in 88 ms on Tawfiq-PC (executor 0) (47/48)
268: 18/02/05 13:08:49 INFO TaskSetManager: Finished task 47.0 in stage 1.0 (TID 95) in 63 ms on Tawfiq-PC (executor 0) (48/48)
269: 18/02/05 13:08:49 INFO TaskSchedulerImpl: Removed TaskSet 1.0, whose tasks have all completed, from pool 
270: 18/02/05 13:08:49 INFO DAGScheduler: ResultStage 1 (runJob at SparkHadoopWriter.scala:78) finished in 7.104 s
271: 18/02/05 13:08:49 INFO DAGScheduler: Job 0 finished: runJob at SparkHadoopWriter.scala:78, took 89.102733 s
272: 18/02/05 13:08:50 INFO SparkHadoopWriter: Job job_20180205130720_0005 committed.
273: 18/02/05 13:08:50 INFO SparkContext: Invoking stop() from shutdown hook
274: 18/02/05 13:08:50 INFO SparkUI: Stopped Spark web UI at http://tawfiq-pc.mobility.unimelb.net.au:4043
275: 18/02/05 13:08:50 INFO MesosCoarseGrainedSchedulerBackend: Shutting down all executors
276: 18/02/05 13:08:50 INFO CoarseGrainedSchedulerBackend$DriverEndpoint: Asking each executor to shut down
277: 18/02/05 13:08:50 INFO MesosCoarseGrainedSchedulerBackend: Mesos task 0 is now TASK_FINISHED
278: I0205 13:08:50.455268 21373 sched.cpp:2021] Asked to stop the driver
279: I0205 13:08:50.455590 20129 sched.cpp:1203] Stopping framework c0393525-27a6-4604-bbbb-b86657dabc56-0008
280: 18/02/05 13:08:50 INFO MesosCoarseGrainedSchedulerBackend: driver.run() returned with code DRIVER_STOPPED
281: 18/02/05 13:08:50 INFO MapOutputTrackerMasterEndpoint: MapOutputTrackerMasterEndpoint stopped!
282: 18/02/05 13:08:50 INFO MemoryStore: MemoryStore cleared
283: 18/02/05 13:08:50 INFO BlockManager: BlockManager stopped
284: 18/02/05 13:08:50 INFO BlockManagerMaster: BlockManagerMaster stopped
285: 18/02/05 13:08:50 INFO OutputCommitCoordinator$OutputCommitCoordinatorEndpoint: OutputCommitCoordinator stopped!
286: 18/02/05 13:08:50 INFO SparkContext: Successfully stopped SparkContext
287: 18/02/05 13:08:50 INFO ShutdownHookManager: Shutdown hook called
288: 18/02/05 13:08:50 INFO ShutdownHookManager: Deleting directory /tmp/spark-37d64479-a253-48d7-b9a6-d4089c9dbe2d
289: 18/02/05 13:08:50 INFO ShutdownHookManager: Deleting directory /tmp/spark-404c8126-f444-43da-aa95-dc63e3764d57
